[2025-10-01: 03:49:00] [model_sync] > Error syncing models from NN API: ('Connection aborted.', RemoteDisconnected('Remote end closed connection without response')) >> (<class 'requests.exceptions.ConnectionError'>, ConnectionError(ProtocolError('Connection aborted.', RemoteDisconnected('Remote end closed connection without response'))), <traceback object at 0x7a54090d9580>)
Traceback (most recent call last):
  File "/usr/local/lib/python3.11/site-packages/urllib3/connectionpool.py", line 789, in urlopen
    response = self._make_request(
               ^^^^^^^^^^^^^^^^^^^
  File "/usr/local/lib/python3.11/site-packages/urllib3/connectionpool.py", line 536, in _make_request
    response = conn.getresponse()
               ^^^^^^^^^^^^^^^^^^
  File "/usr/local/lib/python3.11/site-packages/urllib3/connection.py", line 507, in getresponse
    httplib_response = super().getresponse()
                       ^^^^^^^^^^^^^^^^^^^^^
  File "/usr/local/lib/python3.11/http/client.py", line 1395, in getresponse
    response.begin()
  File "/usr/local/lib/python3.11/http/client.py", line 325, in begin
    version, status, reason = self._read_status()
                              ^^^^^^^^^^^^^^^^^^^
  File "/usr/local/lib/python3.11/http/client.py", line 294, in _read_status
    raise RemoteDisconnected("Remote end closed connection without"
http.client.RemoteDisconnected: Remote end closed connection without response

During handling of the above exception, another exception occurred:

Traceback (most recent call last):
  File "/usr/local/lib/python3.11/site-packages/requests/adapters.py", line 667, in send
    resp = conn.urlopen(
           ^^^^^^^^^^^^^
  File "/usr/local/lib/python3.11/site-packages/urllib3/connectionpool.py", line 843, in urlopen
    retries = retries.increment(
              ^^^^^^^^^^^^^^^^^^
  File "/usr/local/lib/python3.11/site-packages/urllib3/util/retry.py", line 474, in increment
    raise reraise(type(error), error, _stacktrace)
          ^^^^^^^^^^^^^^^^^^^^^^^^^^^^^^^^^^^^^^^^
  File "/usr/local/lib/python3.11/site-packages/urllib3/util/util.py", line 38, in reraise
    raise value.with_traceback(tb)
  File "/usr/local/lib/python3.11/site-packages/urllib3/connectionpool.py", line 789, in urlopen
    response = self._make_request(
               ^^^^^^^^^^^^^^^^^^^
  File "/usr/local/lib/python3.11/site-packages/urllib3/connectionpool.py", line 536, in _make_request
    response = conn.getresponse()
               ^^^^^^^^^^^^^^^^^^
  File "/usr/local/lib/python3.11/site-packages/urllib3/connection.py", line 507, in getresponse
    httplib_response = super().getresponse()
                       ^^^^^^^^^^^^^^^^^^^^^
  File "/usr/local/lib/python3.11/http/client.py", line 1395, in getresponse
    response.begin()
  File "/usr/local/lib/python3.11/http/client.py", line 325, in begin
    version, status, reason = self._read_status()
                              ^^^^^^^^^^^^^^^^^^^
  File "/usr/local/lib/python3.11/http/client.py", line 294, in _read_status
    raise RemoteDisconnected("Remote end closed connection without"
urllib3.exceptions.ProtocolError: ('Connection aborted.', RemoteDisconnected('Remote end closed connection without response'))

During handling of the above exception, another exception occurred:

Traceback (most recent call last):
  File "/app/src/services/model_sync.py", line 22, in sync_models_with_nn_api
    nn_models_response = nn_client.getAvailableModels()
                         ^^^^^^^^^^^^^^^^^^^^^^^^^^^^^^
  File "/app/src/cloudServices/nnApiConnections.py", line 146, in getAvailableModels
    response = requests.get(url, headers=headers)
               ^^^^^^^^^^^^^^^^^^^^^^^^^^^^^^^^^^
  File "/usr/local/lib/python3.11/site-packages/requests/api.py", line 73, in get
    return request("get", url, params=params, **kwargs)
           ^^^^^^^^^^^^^^^^^^^^^^^^^^^^^^^^^^^^^^^^^^^^
  File "/usr/local/lib/python3.11/site-packages/requests/api.py", line 59, in request
    return session.request(method=method, url=url, **kwargs)
           ^^^^^^^^^^^^^^^^^^^^^^^^^^^^^^^^^^^^^^^^^^^^^^^^^
  File "/usr/local/lib/python3.11/site-packages/requests/sessions.py", line 589, in request
    resp = self.send(prep, **send_kwargs)
           ^^^^^^^^^^^^^^^^^^^^^^^^^^^^^^
  File "/usr/local/lib/python3.11/site-packages/requests/sessions.py", line 703, in send
    r = adapter.send(request, **kwargs)
        ^^^^^^^^^^^^^^^^^^^^^^^^^^^^^^^
  File "/usr/local/lib/python3.11/site-packages/requests/adapters.py", line 682, in send
    raise ConnectionError(err, request=request)
requests.exceptions.ConnectionError: ('Connection aborted.', RemoteDisconnected('Remote end closed connection without response'))
[2025-10-01: 03:49:01] [model_sync] > Error syncing models from NN API: ('Connection aborted.', RemoteDisconnected('Remote end closed connection without response')) >> (<class 'requests.exceptions.ConnectionError'>, ConnectionError(ProtocolError('Connection aborted.', RemoteDisconnected('Remote end closed connection without response'))), <traceback object at 0x7cb492883840>)
Traceback (most recent call last):
  File "/usr/local/lib/python3.11/site-packages/urllib3/connectionpool.py", line 789, in urlopen
    response = self._make_request(
               ^^^^^^^^^^^^^^^^^^^
  File "/usr/local/lib/python3.11/site-packages/urllib3/connectionpool.py", line 536, in _make_request
    response = conn.getresponse()
               ^^^^^^^^^^^^^^^^^^
  File "/usr/local/lib/python3.11/site-packages/urllib3/connection.py", line 507, in getresponse
    httplib_response = super().getresponse()
                       ^^^^^^^^^^^^^^^^^^^^^
  File "/usr/local/lib/python3.11/http/client.py", line 1395, in getresponse
    response.begin()
  File "/usr/local/lib/python3.11/http/client.py", line 325, in begin
    version, status, reason = self._read_status()
                              ^^^^^^^^^^^^^^^^^^^
  File "/usr/local/lib/python3.11/http/client.py", line 294, in _read_status
    raise RemoteDisconnected("Remote end closed connection without"
http.client.RemoteDisconnected: Remote end closed connection without response

During handling of the above exception, another exception occurred:

Traceback (most recent call last):
  File "/usr/local/lib/python3.11/site-packages/requests/adapters.py", line 667, in send
    resp = conn.urlopen(
           ^^^^^^^^^^^^^
  File "/usr/local/lib/python3.11/site-packages/urllib3/connectionpool.py", line 843, in urlopen
    retries = retries.increment(
              ^^^^^^^^^^^^^^^^^^
  File "/usr/local/lib/python3.11/site-packages/urllib3/util/retry.py", line 474, in increment
    raise reraise(type(error), error, _stacktrace)
          ^^^^^^^^^^^^^^^^^^^^^^^^^^^^^^^^^^^^^^^^
  File "/usr/local/lib/python3.11/site-packages/urllib3/util/util.py", line 38, in reraise
    raise value.with_traceback(tb)
  File "/usr/local/lib/python3.11/site-packages/urllib3/connectionpool.py", line 789, in urlopen
    response = self._make_request(
               ^^^^^^^^^^^^^^^^^^^
  File "/usr/local/lib/python3.11/site-packages/urllib3/connectionpool.py", line 536, in _make_request
    response = conn.getresponse()
               ^^^^^^^^^^^^^^^^^^
  File "/usr/local/lib/python3.11/site-packages/urllib3/connection.py", line 507, in getresponse
    httplib_response = super().getresponse()
                       ^^^^^^^^^^^^^^^^^^^^^
  File "/usr/local/lib/python3.11/http/client.py", line 1395, in getresponse
    response.begin()
  File "/usr/local/lib/python3.11/http/client.py", line 325, in begin
    version, status, reason = self._read_status()
                              ^^^^^^^^^^^^^^^^^^^
  File "/usr/local/lib/python3.11/http/client.py", line 294, in _read_status
    raise RemoteDisconnected("Remote end closed connection without"
urllib3.exceptions.ProtocolError: ('Connection aborted.', RemoteDisconnected('Remote end closed connection without response'))

During handling of the above exception, another exception occurred:

Traceback (most recent call last):
  File "/app/src/services/model_sync.py", line 22, in sync_models_with_nn_api
    nn_models_response = nn_client.getAvailableModels()
                         ^^^^^^^^^^^^^^^^^^^^^^^^^^^^^^
  File "/app/src/cloudServices/nnApiConnections.py", line 146, in getAvailableModels
    response = requests.get(url, headers=headers)
               ^^^^^^^^^^^^^^^^^^^^^^^^^^^^^^^^^^
  File "/usr/local/lib/python3.11/site-packages/requests/api.py", line 73, in get
    return request("get", url, params=params, **kwargs)
           ^^^^^^^^^^^^^^^^^^^^^^^^^^^^^^^^^^^^^^^^^^^^
  File "/usr/local/lib/python3.11/site-packages/requests/api.py", line 59, in request
    return session.request(method=method, url=url, **kwargs)
           ^^^^^^^^^^^^^^^^^^^^^^^^^^^^^^^^^^^^^^^^^^^^^^^^^
  File "/usr/local/lib/python3.11/site-packages/requests/sessions.py", line 589, in request
    resp = self.send(prep, **send_kwargs)
           ^^^^^^^^^^^^^^^^^^^^^^^^^^^^^^
  File "/usr/local/lib/python3.11/site-packages/requests/sessions.py", line 703, in send
    r = adapter.send(request, **kwargs)
        ^^^^^^^^^^^^^^^^^^^^^^^^^^^^^^^
  File "/usr/local/lib/python3.11/site-packages/requests/adapters.py", line 682, in send
    raise ConnectionError(err, request=request)
requests.exceptions.ConnectionError: ('Connection aborted.', RemoteDisconnected('Remote end closed connection without response'))
[2025-10-01: 03:49:02] [model_sync] > Error syncing models from NN API: ('Connection aborted.', RemoteDisconnected('Remote end closed connection without response')) >> (<class 'requests.exceptions.ConnectionError'>, ConnectionError(ProtocolError('Connection aborted.', RemoteDisconnected('Remote end closed connection without response'))), <traceback object at 0x7caaf23ab880>)
Traceback (most recent call last):
  File "/usr/local/lib/python3.11/site-packages/urllib3/connectionpool.py", line 789, in urlopen
    response = self._make_request(
               ^^^^^^^^^^^^^^^^^^^
  File "/usr/local/lib/python3.11/site-packages/urllib3/connectionpool.py", line 536, in _make_request
    response = conn.getresponse()
               ^^^^^^^^^^^^^^^^^^
  File "/usr/local/lib/python3.11/site-packages/urllib3/connection.py", line 507, in getresponse
    httplib_response = super().getresponse()
                       ^^^^^^^^^^^^^^^^^^^^^
  File "/usr/local/lib/python3.11/http/client.py", line 1395, in getresponse
    response.begin()
  File "/usr/local/lib/python3.11/http/client.py", line 325, in begin
    version, status, reason = self._read_status()
                              ^^^^^^^^^^^^^^^^^^^
  File "/usr/local/lib/python3.11/http/client.py", line 294, in _read_status
    raise RemoteDisconnected("Remote end closed connection without"
http.client.RemoteDisconnected: Remote end closed connection without response

During handling of the above exception, another exception occurred:

Traceback (most recent call last):
  File "/usr/local/lib/python3.11/site-packages/requests/adapters.py", line 667, in send
    resp = conn.urlopen(
           ^^^^^^^^^^^^^
  File "/usr/local/lib/python3.11/site-packages/urllib3/connectionpool.py", line 843, in urlopen
    retries = retries.increment(
              ^^^^^^^^^^^^^^^^^^
  File "/usr/local/lib/python3.11/site-packages/urllib3/util/retry.py", line 474, in increment
    raise reraise(type(error), error, _stacktrace)
          ^^^^^^^^^^^^^^^^^^^^^^^^^^^^^^^^^^^^^^^^
  File "/usr/local/lib/python3.11/site-packages/urllib3/util/util.py", line 38, in reraise
    raise value.with_traceback(tb)
  File "/usr/local/lib/python3.11/site-packages/urllib3/connectionpool.py", line 789, in urlopen
    response = self._make_request(
               ^^^^^^^^^^^^^^^^^^^
  File "/usr/local/lib/python3.11/site-packages/urllib3/connectionpool.py", line 536, in _make_request
    response = conn.getresponse()
               ^^^^^^^^^^^^^^^^^^
  File "/usr/local/lib/python3.11/site-packages/urllib3/connection.py", line 507, in getresponse
    httplib_response = super().getresponse()
                       ^^^^^^^^^^^^^^^^^^^^^
  File "/usr/local/lib/python3.11/http/client.py", line 1395, in getresponse
    response.begin()
  File "/usr/local/lib/python3.11/http/client.py", line 325, in begin
    version, status, reason = self._read_status()
                              ^^^^^^^^^^^^^^^^^^^
  File "/usr/local/lib/python3.11/http/client.py", line 294, in _read_status
    raise RemoteDisconnected("Remote end closed connection without"
urllib3.exceptions.ProtocolError: ('Connection aborted.', RemoteDisconnected('Remote end closed connection without response'))

During handling of the above exception, another exception occurred:

Traceback (most recent call last):
  File "/app/src/services/model_sync.py", line 22, in sync_models_with_nn_api
    nn_models_response = nn_client.getAvailableModels()
                         ^^^^^^^^^^^^^^^^^^^^^^^^^^^^^^
  File "/app/src/cloudServices/nnApiConnections.py", line 146, in getAvailableModels
    response = requests.get(url, headers=headers)
               ^^^^^^^^^^^^^^^^^^^^^^^^^^^^^^^^^^
  File "/usr/local/lib/python3.11/site-packages/requests/api.py", line 73, in get
    return request("get", url, params=params, **kwargs)
           ^^^^^^^^^^^^^^^^^^^^^^^^^^^^^^^^^^^^^^^^^^^^
  File "/usr/local/lib/python3.11/site-packages/requests/api.py", line 59, in request
    return session.request(method=method, url=url, **kwargs)
           ^^^^^^^^^^^^^^^^^^^^^^^^^^^^^^^^^^^^^^^^^^^^^^^^^
  File "/usr/local/lib/python3.11/site-packages/requests/sessions.py", line 589, in request
    resp = self.send(prep, **send_kwargs)
           ^^^^^^^^^^^^^^^^^^^^^^^^^^^^^^
  File "/usr/local/lib/python3.11/site-packages/requests/sessions.py", line 703, in send
    r = adapter.send(request, **kwargs)
        ^^^^^^^^^^^^^^^^^^^^^^^^^^^^^^^
  File "/usr/local/lib/python3.11/site-packages/requests/adapters.py", line 682, in send
    raise ConnectionError(err, request=request)
requests.exceptions.ConnectionError: ('Connection aborted.', RemoteDisconnected('Remote end closed connection without response'))
[2025-10-01: 04:27:22] [model_sync] > Error syncing models from NN API: ('Connection aborted.', RemoteDisconnected('Remote end closed connection without response')) >> (<class 'requests.exceptions.ConnectionError'>, ConnectionError(ProtocolError('Connection aborted.', RemoteDisconnected('Remote end closed connection without response'))), <traceback object at 0x7f2e50d851c0>)
Traceback (most recent call last):
  File "/usr/local/lib/python3.11/site-packages/urllib3/connectionpool.py", line 789, in urlopen
    response = self._make_request(
               ^^^^^^^^^^^^^^^^^^^
  File "/usr/local/lib/python3.11/site-packages/urllib3/connectionpool.py", line 536, in _make_request
    response = conn.getresponse()
               ^^^^^^^^^^^^^^^^^^
  File "/usr/local/lib/python3.11/site-packages/urllib3/connection.py", line 507, in getresponse
    httplib_response = super().getresponse()
                       ^^^^^^^^^^^^^^^^^^^^^
  File "/usr/local/lib/python3.11/http/client.py", line 1395, in getresponse
    response.begin()
  File "/usr/local/lib/python3.11/http/client.py", line 325, in begin
    version, status, reason = self._read_status()
                              ^^^^^^^^^^^^^^^^^^^
  File "/usr/local/lib/python3.11/http/client.py", line 294, in _read_status
    raise RemoteDisconnected("Remote end closed connection without"
http.client.RemoteDisconnected: Remote end closed connection without response

During handling of the above exception, another exception occurred:

Traceback (most recent call last):
  File "/usr/local/lib/python3.11/site-packages/requests/adapters.py", line 667, in send
    resp = conn.urlopen(
           ^^^^^^^^^^^^^
  File "/usr/local/lib/python3.11/site-packages/urllib3/connectionpool.py", line 843, in urlopen
    retries = retries.increment(
              ^^^^^^^^^^^^^^^^^^
  File "/usr/local/lib/python3.11/site-packages/urllib3/util/retry.py", line 474, in increment
    raise reraise(type(error), error, _stacktrace)
          ^^^^^^^^^^^^^^^^^^^^^^^^^^^^^^^^^^^^^^^^
  File "/usr/local/lib/python3.11/site-packages/urllib3/util/util.py", line 38, in reraise
    raise value.with_traceback(tb)
  File "/usr/local/lib/python3.11/site-packages/urllib3/connectionpool.py", line 789, in urlopen
    response = self._make_request(
               ^^^^^^^^^^^^^^^^^^^
  File "/usr/local/lib/python3.11/site-packages/urllib3/connectionpool.py", line 536, in _make_request
    response = conn.getresponse()
               ^^^^^^^^^^^^^^^^^^
  File "/usr/local/lib/python3.11/site-packages/urllib3/connection.py", line 507, in getresponse
    httplib_response = super().getresponse()
                       ^^^^^^^^^^^^^^^^^^^^^
  File "/usr/local/lib/python3.11/http/client.py", line 1395, in getresponse
    response.begin()
  File "/usr/local/lib/python3.11/http/client.py", line 325, in begin
    version, status, reason = self._read_status()
                              ^^^^^^^^^^^^^^^^^^^
  File "/usr/local/lib/python3.11/http/client.py", line 294, in _read_status
    raise RemoteDisconnected("Remote end closed connection without"
urllib3.exceptions.ProtocolError: ('Connection aborted.', RemoteDisconnected('Remote end closed connection without response'))

During handling of the above exception, another exception occurred:

Traceback (most recent call last):
  File "/app/src/services/model_sync.py", line 22, in sync_models_with_nn_api
    nn_models_response = nn_client.getAvailableModels()
                         ^^^^^^^^^^^^^^^^^^^^^^^^^^^^^^
  File "/app/src/cloudServices/nnApiConnections.py", line 146, in getAvailableModels
    response = requests.get(url, headers=headers)
               ^^^^^^^^^^^^^^^^^^^^^^^^^^^^^^^^^^
  File "/usr/local/lib/python3.11/site-packages/requests/api.py", line 73, in get
    return request("get", url, params=params, **kwargs)
           ^^^^^^^^^^^^^^^^^^^^^^^^^^^^^^^^^^^^^^^^^^^^
  File "/usr/local/lib/python3.11/site-packages/requests/api.py", line 59, in request
    return session.request(method=method, url=url, **kwargs)
           ^^^^^^^^^^^^^^^^^^^^^^^^^^^^^^^^^^^^^^^^^^^^^^^^^
  File "/usr/local/lib/python3.11/site-packages/requests/sessions.py", line 589, in request
    resp = self.send(prep, **send_kwargs)
           ^^^^^^^^^^^^^^^^^^^^^^^^^^^^^^
  File "/usr/local/lib/python3.11/site-packages/requests/sessions.py", line 703, in send
    r = adapter.send(request, **kwargs)
        ^^^^^^^^^^^^^^^^^^^^^^^^^^^^^^^
  File "/usr/local/lib/python3.11/site-packages/requests/adapters.py", line 682, in send
    raise ConnectionError(err, request=request)
requests.exceptions.ConnectionError: ('Connection aborted.', RemoteDisconnected('Remote end closed connection without response'))
[2025-10-01: 04:27:23] [model_sync] > Error syncing models from NN API: ('Connection aborted.', RemoteDisconnected('Remote end closed connection without response')) >> (<class 'requests.exceptions.ConnectionError'>, ConnectionError(ProtocolError('Connection aborted.', RemoteDisconnected('Remote end closed connection without response'))), <traceback object at 0x79c9789775c0>)
Traceback (most recent call last):
  File "/usr/local/lib/python3.11/site-packages/urllib3/connectionpool.py", line 789, in urlopen
    response = self._make_request(
               ^^^^^^^^^^^^^^^^^^^
  File "/usr/local/lib/python3.11/site-packages/urllib3/connectionpool.py", line 536, in _make_request
    response = conn.getresponse()
               ^^^^^^^^^^^^^^^^^^
  File "/usr/local/lib/python3.11/site-packages/urllib3/connection.py", line 507, in getresponse
    httplib_response = super().getresponse()
                       ^^^^^^^^^^^^^^^^^^^^^
  File "/usr/local/lib/python3.11/http/client.py", line 1395, in getresponse
    response.begin()
  File "/usr/local/lib/python3.11/http/client.py", line 325, in begin
    version, status, reason = self._read_status()
                              ^^^^^^^^^^^^^^^^^^^
  File "/usr/local/lib/python3.11/http/client.py", line 294, in _read_status
    raise RemoteDisconnected("Remote end closed connection without"
http.client.RemoteDisconnected: Remote end closed connection without response

During handling of the above exception, another exception occurred:

Traceback (most recent call last):
  File "/usr/local/lib/python3.11/site-packages/requests/adapters.py", line 667, in send
    resp = conn.urlopen(
           ^^^^^^^^^^^^^
  File "/usr/local/lib/python3.11/site-packages/urllib3/connectionpool.py", line 843, in urlopen
    retries = retries.increment(
              ^^^^^^^^^^^^^^^^^^
  File "/usr/local/lib/python3.11/site-packages/urllib3/util/retry.py", line 474, in increment
    raise reraise(type(error), error, _stacktrace)
          ^^^^^^^^^^^^^^^^^^^^^^^^^^^^^^^^^^^^^^^^
  File "/usr/local/lib/python3.11/site-packages/urllib3/util/util.py", line 38, in reraise
    raise value.with_traceback(tb)
  File "/usr/local/lib/python3.11/site-packages/urllib3/connectionpool.py", line 789, in urlopen
    response = self._make_request(
               ^^^^^^^^^^^^^^^^^^^
  File "/usr/local/lib/python3.11/site-packages/urllib3/connectionpool.py", line 536, in _make_request
    response = conn.getresponse()
               ^^^^^^^^^^^^^^^^^^
  File "/usr/local/lib/python3.11/site-packages/urllib3/connection.py", line 507, in getresponse
    httplib_response = super().getresponse()
                       ^^^^^^^^^^^^^^^^^^^^^
  File "/usr/local/lib/python3.11/http/client.py", line 1395, in getresponse
    response.begin()
  File "/usr/local/lib/python3.11/http/client.py", line 325, in begin
    version, status, reason = self._read_status()
                              ^^^^^^^^^^^^^^^^^^^
  File "/usr/local/lib/python3.11/http/client.py", line 294, in _read_status
    raise RemoteDisconnected("Remote end closed connection without"
urllib3.exceptions.ProtocolError: ('Connection aborted.', RemoteDisconnected('Remote end closed connection without response'))

During handling of the above exception, another exception occurred:

Traceback (most recent call last):
  File "/app/src/services/model_sync.py", line 22, in sync_models_with_nn_api
    nn_models_response = nn_client.getAvailableModels()
                         ^^^^^^^^^^^^^^^^^^^^^^^^^^^^^^
  File "/app/src/cloudServices/nnApiConnections.py", line 146, in getAvailableModels
    response = requests.get(url, headers=headers)
               ^^^^^^^^^^^^^^^^^^^^^^^^^^^^^^^^^^
  File "/usr/local/lib/python3.11/site-packages/requests/api.py", line 73, in get
    return request("get", url, params=params, **kwargs)
           ^^^^^^^^^^^^^^^^^^^^^^^^^^^^^^^^^^^^^^^^^^^^
  File "/usr/local/lib/python3.11/site-packages/requests/api.py", line 59, in request
    return session.request(method=method, url=url, **kwargs)
           ^^^^^^^^^^^^^^^^^^^^^^^^^^^^^^^^^^^^^^^^^^^^^^^^^
  File "/usr/local/lib/python3.11/site-packages/requests/sessions.py", line 589, in request
    resp = self.send(prep, **send_kwargs)
           ^^^^^^^^^^^^^^^^^^^^^^^^^^^^^^
  File "/usr/local/lib/python3.11/site-packages/requests/sessions.py", line 703, in send
    r = adapter.send(request, **kwargs)
        ^^^^^^^^^^^^^^^^^^^^^^^^^^^^^^^
  File "/usr/local/lib/python3.11/site-packages/requests/adapters.py", line 682, in send
    raise ConnectionError(err, request=request)
requests.exceptions.ConnectionError: ('Connection aborted.', RemoteDisconnected('Remote end closed connection without response'))
[2025-10-01: 04:27:24] [model_sync] > Error syncing models from NN API: ('Connection aborted.', RemoteDisconnected('Remote end closed connection without response')) >> (<class 'requests.exceptions.ConnectionError'>, ConnectionError(ProtocolError('Connection aborted.', RemoteDisconnected('Remote end closed connection without response'))), <traceback object at 0x75343a3f3580>)
Traceback (most recent call last):
  File "/usr/local/lib/python3.11/site-packages/urllib3/connectionpool.py", line 789, in urlopen
    response = self._make_request(
               ^^^^^^^^^^^^^^^^^^^
  File "/usr/local/lib/python3.11/site-packages/urllib3/connectionpool.py", line 536, in _make_request
    response = conn.getresponse()
               ^^^^^^^^^^^^^^^^^^
  File "/usr/local/lib/python3.11/site-packages/urllib3/connection.py", line 507, in getresponse
    httplib_response = super().getresponse()
                       ^^^^^^^^^^^^^^^^^^^^^
  File "/usr/local/lib/python3.11/http/client.py", line 1395, in getresponse
    response.begin()
  File "/usr/local/lib/python3.11/http/client.py", line 325, in begin
    version, status, reason = self._read_status()
                              ^^^^^^^^^^^^^^^^^^^
  File "/usr/local/lib/python3.11/http/client.py", line 294, in _read_status
    raise RemoteDisconnected("Remote end closed connection without"
http.client.RemoteDisconnected: Remote end closed connection without response

During handling of the above exception, another exception occurred:

Traceback (most recent call last):
  File "/usr/local/lib/python3.11/site-packages/requests/adapters.py", line 667, in send
    resp = conn.urlopen(
           ^^^^^^^^^^^^^
  File "/usr/local/lib/python3.11/site-packages/urllib3/connectionpool.py", line 843, in urlopen
    retries = retries.increment(
              ^^^^^^^^^^^^^^^^^^
  File "/usr/local/lib/python3.11/site-packages/urllib3/util/retry.py", line 474, in increment
    raise reraise(type(error), error, _stacktrace)
          ^^^^^^^^^^^^^^^^^^^^^^^^^^^^^^^^^^^^^^^^
  File "/usr/local/lib/python3.11/site-packages/urllib3/util/util.py", line 38, in reraise
    raise value.with_traceback(tb)
  File "/usr/local/lib/python3.11/site-packages/urllib3/connectionpool.py", line 789, in urlopen
    response = self._make_request(
               ^^^^^^^^^^^^^^^^^^^
  File "/usr/local/lib/python3.11/site-packages/urllib3/connectionpool.py", line 536, in _make_request
    response = conn.getresponse()
               ^^^^^^^^^^^^^^^^^^
  File "/usr/local/lib/python3.11/site-packages/urllib3/connection.py", line 507, in getresponse
    httplib_response = super().getresponse()
                       ^^^^^^^^^^^^^^^^^^^^^
  File "/usr/local/lib/python3.11/http/client.py", line 1395, in getresponse
    response.begin()
  File "/usr/local/lib/python3.11/http/client.py", line 325, in begin
    version, status, reason = self._read_status()
                              ^^^^^^^^^^^^^^^^^^^
  File "/usr/local/lib/python3.11/http/client.py", line 294, in _read_status
    raise RemoteDisconnected("Remote end closed connection without"
urllib3.exceptions.ProtocolError: ('Connection aborted.', RemoteDisconnected('Remote end closed connection without response'))

During handling of the above exception, another exception occurred:

Traceback (most recent call last):
  File "/app/src/services/model_sync.py", line 22, in sync_models_with_nn_api
    nn_models_response = nn_client.getAvailableModels()
                         ^^^^^^^^^^^^^^^^^^^^^^^^^^^^^^
  File "/app/src/cloudServices/nnApiConnections.py", line 146, in getAvailableModels
    response = requests.get(url, headers=headers)
               ^^^^^^^^^^^^^^^^^^^^^^^^^^^^^^^^^^
  File "/usr/local/lib/python3.11/site-packages/requests/api.py", line 73, in get
    return request("get", url, params=params, **kwargs)
           ^^^^^^^^^^^^^^^^^^^^^^^^^^^^^^^^^^^^^^^^^^^^
  File "/usr/local/lib/python3.11/site-packages/requests/api.py", line 59, in request
    return session.request(method=method, url=url, **kwargs)
           ^^^^^^^^^^^^^^^^^^^^^^^^^^^^^^^^^^^^^^^^^^^^^^^^^
  File "/usr/local/lib/python3.11/site-packages/requests/sessions.py", line 589, in request
    resp = self.send(prep, **send_kwargs)
           ^^^^^^^^^^^^^^^^^^^^^^^^^^^^^^
  File "/usr/local/lib/python3.11/site-packages/requests/sessions.py", line 703, in send
    r = adapter.send(request, **kwargs)
        ^^^^^^^^^^^^^^^^^^^^^^^^^^^^^^^
  File "/usr/local/lib/python3.11/site-packages/requests/adapters.py", line 682, in send
    raise ConnectionError(err, request=request)
requests.exceptions.ConnectionError: ('Connection aborted.', RemoteDisconnected('Remote end closed connection without response'))
[2025-10-01: 04:42:50] [model_sync] > Error syncing models from NN API: ('Connection aborted.', RemoteDisconnected('Remote end closed connection without response')) >> (<class 'requests.exceptions.ConnectionError'>, ConnectionError(ProtocolError('Connection aborted.', RemoteDisconnected('Remote end closed connection without response'))), <traceback object at 0x76467f814d00>)
Traceback (most recent call last):
  File "/usr/local/lib/python3.11/site-packages/urllib3/connectionpool.py", line 789, in urlopen
    response = self._make_request(
               ^^^^^^^^^^^^^^^^^^^
  File "/usr/local/lib/python3.11/site-packages/urllib3/connectionpool.py", line 536, in _make_request
    response = conn.getresponse()
               ^^^^^^^^^^^^^^^^^^
  File "/usr/local/lib/python3.11/site-packages/urllib3/connection.py", line 507, in getresponse
    httplib_response = super().getresponse()
                       ^^^^^^^^^^^^^^^^^^^^^
  File "/usr/local/lib/python3.11/http/client.py", line 1395, in getresponse
    response.begin()
  File "/usr/local/lib/python3.11/http/client.py", line 325, in begin
    version, status, reason = self._read_status()
                              ^^^^^^^^^^^^^^^^^^^
  File "/usr/local/lib/python3.11/http/client.py", line 294, in _read_status
    raise RemoteDisconnected("Remote end closed connection without"
http.client.RemoteDisconnected: Remote end closed connection without response

During handling of the above exception, another exception occurred:

Traceback (most recent call last):
  File "/usr/local/lib/python3.11/site-packages/requests/adapters.py", line 667, in send
    resp = conn.urlopen(
           ^^^^^^^^^^^^^
  File "/usr/local/lib/python3.11/site-packages/urllib3/connectionpool.py", line 843, in urlopen
    retries = retries.increment(
              ^^^^^^^^^^^^^^^^^^
  File "/usr/local/lib/python3.11/site-packages/urllib3/util/retry.py", line 474, in increment
    raise reraise(type(error), error, _stacktrace)
          ^^^^^^^^^^^^^^^^^^^^^^^^^^^^^^^^^^^^^^^^
  File "/usr/local/lib/python3.11/site-packages/urllib3/util/util.py", line 38, in reraise
    raise value.with_traceback(tb)
  File "/usr/local/lib/python3.11/site-packages/urllib3/connectionpool.py", line 789, in urlopen
    response = self._make_request(
               ^^^^^^^^^^^^^^^^^^^
  File "/usr/local/lib/python3.11/site-packages/urllib3/connectionpool.py", line 536, in _make_request
    response = conn.getresponse()
               ^^^^^^^^^^^^^^^^^^
  File "/usr/local/lib/python3.11/site-packages/urllib3/connection.py", line 507, in getresponse
    httplib_response = super().getresponse()
                       ^^^^^^^^^^^^^^^^^^^^^
  File "/usr/local/lib/python3.11/http/client.py", line 1395, in getresponse
    response.begin()
  File "/usr/local/lib/python3.11/http/client.py", line 325, in begin
    version, status, reason = self._read_status()
                              ^^^^^^^^^^^^^^^^^^^
  File "/usr/local/lib/python3.11/http/client.py", line 294, in _read_status
    raise RemoteDisconnected("Remote end closed connection without"
urllib3.exceptions.ProtocolError: ('Connection aborted.', RemoteDisconnected('Remote end closed connection without response'))

During handling of the above exception, another exception occurred:

Traceback (most recent call last):
  File "/app/src/services/model_sync.py", line 22, in sync_models_with_nn_api
    nn_models_response = nn_client.getAvailableModels()
                         ^^^^^^^^^^^^^^^^^^^^^^^^^^^^^^
  File "/app/src/cloudServices/nnApiConnections.py", line 146, in getAvailableModels
    response = requests.get(url, headers=headers)
               ^^^^^^^^^^^^^^^^^^^^^^^^^^^^^^^^^^
  File "/usr/local/lib/python3.11/site-packages/requests/api.py", line 73, in get
    return request("get", url, params=params, **kwargs)
           ^^^^^^^^^^^^^^^^^^^^^^^^^^^^^^^^^^^^^^^^^^^^
  File "/usr/local/lib/python3.11/site-packages/requests/api.py", line 59, in request
    return session.request(method=method, url=url, **kwargs)
           ^^^^^^^^^^^^^^^^^^^^^^^^^^^^^^^^^^^^^^^^^^^^^^^^^
  File "/usr/local/lib/python3.11/site-packages/requests/sessions.py", line 589, in request
    resp = self.send(prep, **send_kwargs)
           ^^^^^^^^^^^^^^^^^^^^^^^^^^^^^^
  File "/usr/local/lib/python3.11/site-packages/requests/sessions.py", line 703, in send
    r = adapter.send(request, **kwargs)
        ^^^^^^^^^^^^^^^^^^^^^^^^^^^^^^^
  File "/usr/local/lib/python3.11/site-packages/requests/adapters.py", line 682, in send
    raise ConnectionError(err, request=request)
requests.exceptions.ConnectionError: ('Connection aborted.', RemoteDisconnected('Remote end closed connection without response'))
[2025-10-01: 04:42:51] [model_sync] > Error syncing models from NN API: ('Connection aborted.', RemoteDisconnected('Remote end closed connection without response')) >> (<class 'requests.exceptions.ConnectionError'>, ConnectionError(ProtocolError('Connection aborted.', RemoteDisconnected('Remote end closed connection without response'))), <traceback object at 0x7aa28aabf6c0>)
Traceback (most recent call last):
  File "/usr/local/lib/python3.11/site-packages/urllib3/connectionpool.py", line 789, in urlopen
    response = self._make_request(
               ^^^^^^^^^^^^^^^^^^^
  File "/usr/local/lib/python3.11/site-packages/urllib3/connectionpool.py", line 536, in _make_request
    response = conn.getresponse()
               ^^^^^^^^^^^^^^^^^^
  File "/usr/local/lib/python3.11/site-packages/urllib3/connection.py", line 507, in getresponse
    httplib_response = super().getresponse()
                       ^^^^^^^^^^^^^^^^^^^^^
  File "/usr/local/lib/python3.11/http/client.py", line 1395, in getresponse
    response.begin()
  File "/usr/local/lib/python3.11/http/client.py", line 325, in begin
    version, status, reason = self._read_status()
                              ^^^^^^^^^^^^^^^^^^^
  File "/usr/local/lib/python3.11/http/client.py", line 294, in _read_status
    raise RemoteDisconnected("Remote end closed connection without"
http.client.RemoteDisconnected: Remote end closed connection without response

During handling of the above exception, another exception occurred:

Traceback (most recent call last):
  File "/usr/local/lib/python3.11/site-packages/requests/adapters.py", line 667, in send
    resp = conn.urlopen(
           ^^^^^^^^^^^^^
  File "/usr/local/lib/python3.11/site-packages/urllib3/connectionpool.py", line 843, in urlopen
    retries = retries.increment(
              ^^^^^^^^^^^^^^^^^^
  File "/usr/local/lib/python3.11/site-packages/urllib3/util/retry.py", line 474, in increment
    raise reraise(type(error), error, _stacktrace)
          ^^^^^^^^^^^^^^^^^^^^^^^^^^^^^^^^^^^^^^^^
  File "/usr/local/lib/python3.11/site-packages/urllib3/util/util.py", line 38, in reraise
    raise value.with_traceback(tb)
  File "/usr/local/lib/python3.11/site-packages/urllib3/connectionpool.py", line 789, in urlopen
    response = self._make_request(
               ^^^^^^^^^^^^^^^^^^^
  File "/usr/local/lib/python3.11/site-packages/urllib3/connectionpool.py", line 536, in _make_request
    response = conn.getresponse()
               ^^^^^^^^^^^^^^^^^^
  File "/usr/local/lib/python3.11/site-packages/urllib3/connection.py", line 507, in getresponse
    httplib_response = super().getresponse()
                       ^^^^^^^^^^^^^^^^^^^^^
  File "/usr/local/lib/python3.11/http/client.py", line 1395, in getresponse
    response.begin()
  File "/usr/local/lib/python3.11/http/client.py", line 325, in begin
    version, status, reason = self._read_status()
                              ^^^^^^^^^^^^^^^^^^^
  File "/usr/local/lib/python3.11/http/client.py", line 294, in _read_status
    raise RemoteDisconnected("Remote end closed connection without"
urllib3.exceptions.ProtocolError: ('Connection aborted.', RemoteDisconnected('Remote end closed connection without response'))

During handling of the above exception, another exception occurred:

Traceback (most recent call last):
  File "/app/src/services/model_sync.py", line 22, in sync_models_with_nn_api
    nn_models_response = nn_client.getAvailableModels()
                         ^^^^^^^^^^^^^^^^^^^^^^^^^^^^^^
  File "/app/src/cloudServices/nnApiConnections.py", line 146, in getAvailableModels
    response = requests.get(url, headers=headers)
               ^^^^^^^^^^^^^^^^^^^^^^^^^^^^^^^^^^
  File "/usr/local/lib/python3.11/site-packages/requests/api.py", line 73, in get
    return request("get", url, params=params, **kwargs)
           ^^^^^^^^^^^^^^^^^^^^^^^^^^^^^^^^^^^^^^^^^^^^
  File "/usr/local/lib/python3.11/site-packages/requests/api.py", line 59, in request
    return session.request(method=method, url=url, **kwargs)
           ^^^^^^^^^^^^^^^^^^^^^^^^^^^^^^^^^^^^^^^^^^^^^^^^^
  File "/usr/local/lib/python3.11/site-packages/requests/sessions.py", line 589, in request
    resp = self.send(prep, **send_kwargs)
           ^^^^^^^^^^^^^^^^^^^^^^^^^^^^^^
  File "/usr/local/lib/python3.11/site-packages/requests/sessions.py", line 703, in send
    r = adapter.send(request, **kwargs)
        ^^^^^^^^^^^^^^^^^^^^^^^^^^^^^^^
  File "/usr/local/lib/python3.11/site-packages/requests/adapters.py", line 682, in send
    raise ConnectionError(err, request=request)
requests.exceptions.ConnectionError: ('Connection aborted.', RemoteDisconnected('Remote end closed connection without response'))
[2025-10-01: 04:42:52] [model_sync] > Error syncing models from NN API: ('Connection aborted.', RemoteDisconnected('Remote end closed connection without response')) >> (<class 'requests.exceptions.ConnectionError'>, ConnectionError(ProtocolError('Connection aborted.', RemoteDisconnected('Remote end closed connection without response'))), <traceback object at 0x715ecb353d40>)
Traceback (most recent call last):
  File "/usr/local/lib/python3.11/site-packages/urllib3/connectionpool.py", line 789, in urlopen
    response = self._make_request(
               ^^^^^^^^^^^^^^^^^^^
  File "/usr/local/lib/python3.11/site-packages/urllib3/connectionpool.py", line 536, in _make_request
    response = conn.getresponse()
               ^^^^^^^^^^^^^^^^^^
  File "/usr/local/lib/python3.11/site-packages/urllib3/connection.py", line 507, in getresponse
    httplib_response = super().getresponse()
                       ^^^^^^^^^^^^^^^^^^^^^
  File "/usr/local/lib/python3.11/http/client.py", line 1395, in getresponse
    response.begin()
  File "/usr/local/lib/python3.11/http/client.py", line 325, in begin
    version, status, reason = self._read_status()
                              ^^^^^^^^^^^^^^^^^^^
  File "/usr/local/lib/python3.11/http/client.py", line 294, in _read_status
    raise RemoteDisconnected("Remote end closed connection without"
http.client.RemoteDisconnected: Remote end closed connection without response

During handling of the above exception, another exception occurred:

Traceback (most recent call last):
  File "/usr/local/lib/python3.11/site-packages/requests/adapters.py", line 667, in send
    resp = conn.urlopen(
           ^^^^^^^^^^^^^
  File "/usr/local/lib/python3.11/site-packages/urllib3/connectionpool.py", line 843, in urlopen
    retries = retries.increment(
              ^^^^^^^^^^^^^^^^^^
  File "/usr/local/lib/python3.11/site-packages/urllib3/util/retry.py", line 474, in increment
    raise reraise(type(error), error, _stacktrace)
          ^^^^^^^^^^^^^^^^^^^^^^^^^^^^^^^^^^^^^^^^
  File "/usr/local/lib/python3.11/site-packages/urllib3/util/util.py", line 38, in reraise
    raise value.with_traceback(tb)
  File "/usr/local/lib/python3.11/site-packages/urllib3/connectionpool.py", line 789, in urlopen
    response = self._make_request(
               ^^^^^^^^^^^^^^^^^^^
  File "/usr/local/lib/python3.11/site-packages/urllib3/connectionpool.py", line 536, in _make_request
    response = conn.getresponse()
               ^^^^^^^^^^^^^^^^^^
  File "/usr/local/lib/python3.11/site-packages/urllib3/connection.py", line 507, in getresponse
    httplib_response = super().getresponse()
                       ^^^^^^^^^^^^^^^^^^^^^
  File "/usr/local/lib/python3.11/http/client.py", line 1395, in getresponse
    response.begin()
  File "/usr/local/lib/python3.11/http/client.py", line 325, in begin
    version, status, reason = self._read_status()
                              ^^^^^^^^^^^^^^^^^^^
  File "/usr/local/lib/python3.11/http/client.py", line 294, in _read_status
    raise RemoteDisconnected("Remote end closed connection without"
urllib3.exceptions.ProtocolError: ('Connection aborted.', RemoteDisconnected('Remote end closed connection without response'))

During handling of the above exception, another exception occurred:

Traceback (most recent call last):
  File "/app/src/services/model_sync.py", line 22, in sync_models_with_nn_api
    nn_models_response = nn_client.getAvailableModels()
                         ^^^^^^^^^^^^^^^^^^^^^^^^^^^^^^
  File "/app/src/cloudServices/nnApiConnections.py", line 146, in getAvailableModels
    response = requests.get(url, headers=headers)
               ^^^^^^^^^^^^^^^^^^^^^^^^^^^^^^^^^^
  File "/usr/local/lib/python3.11/site-packages/requests/api.py", line 73, in get
    return request("get", url, params=params, **kwargs)
           ^^^^^^^^^^^^^^^^^^^^^^^^^^^^^^^^^^^^^^^^^^^^
  File "/usr/local/lib/python3.11/site-packages/requests/api.py", line 59, in request
    return session.request(method=method, url=url, **kwargs)
           ^^^^^^^^^^^^^^^^^^^^^^^^^^^^^^^^^^^^^^^^^^^^^^^^^
  File "/usr/local/lib/python3.11/site-packages/requests/sessions.py", line 589, in request
    resp = self.send(prep, **send_kwargs)
           ^^^^^^^^^^^^^^^^^^^^^^^^^^^^^^
  File "/usr/local/lib/python3.11/site-packages/requests/sessions.py", line 703, in send
    r = adapter.send(request, **kwargs)
        ^^^^^^^^^^^^^^^^^^^^^^^^^^^^^^^
  File "/usr/local/lib/python3.11/site-packages/requests/adapters.py", line 682, in send
    raise ConnectionError(err, request=request)
requests.exceptions.ConnectionError: ('Connection aborted.', RemoteDisconnected('Remote end closed connection without response'))
[2025-10-01: 04:47:26] [model_sync] > Error syncing models from NN API: ('Connection aborted.', RemoteDisconnected('Remote end closed connection without response')) >> (<class 'requests.exceptions.ConnectionError'>, ConnectionError(ProtocolError('Connection aborted.', RemoteDisconnected('Remote end closed connection without response'))), <traceback object at 0x7724e7f1c940>)
Traceback (most recent call last):
  File "/usr/local/lib/python3.11/site-packages/urllib3/connectionpool.py", line 789, in urlopen
    response = self._make_request(
               ^^^^^^^^^^^^^^^^^^^
  File "/usr/local/lib/python3.11/site-packages/urllib3/connectionpool.py", line 536, in _make_request
    response = conn.getresponse()
               ^^^^^^^^^^^^^^^^^^
  File "/usr/local/lib/python3.11/site-packages/urllib3/connection.py", line 507, in getresponse
    httplib_response = super().getresponse()
                       ^^^^^^^^^^^^^^^^^^^^^
  File "/usr/local/lib/python3.11/http/client.py", line 1395, in getresponse
    response.begin()
  File "/usr/local/lib/python3.11/http/client.py", line 325, in begin
    version, status, reason = self._read_status()
                              ^^^^^^^^^^^^^^^^^^^
  File "/usr/local/lib/python3.11/http/client.py", line 294, in _read_status
    raise RemoteDisconnected("Remote end closed connection without"
http.client.RemoteDisconnected: Remote end closed connection without response

During handling of the above exception, another exception occurred:

Traceback (most recent call last):
  File "/usr/local/lib/python3.11/site-packages/requests/adapters.py", line 667, in send
    resp = conn.urlopen(
           ^^^^^^^^^^^^^
  File "/usr/local/lib/python3.11/site-packages/urllib3/connectionpool.py", line 843, in urlopen
    retries = retries.increment(
              ^^^^^^^^^^^^^^^^^^
  File "/usr/local/lib/python3.11/site-packages/urllib3/util/retry.py", line 474, in increment
    raise reraise(type(error), error, _stacktrace)
          ^^^^^^^^^^^^^^^^^^^^^^^^^^^^^^^^^^^^^^^^
  File "/usr/local/lib/python3.11/site-packages/urllib3/util/util.py", line 38, in reraise
    raise value.with_traceback(tb)
  File "/usr/local/lib/python3.11/site-packages/urllib3/connectionpool.py", line 789, in urlopen
    response = self._make_request(
               ^^^^^^^^^^^^^^^^^^^
  File "/usr/local/lib/python3.11/site-packages/urllib3/connectionpool.py", line 536, in _make_request
    response = conn.getresponse()
               ^^^^^^^^^^^^^^^^^^
  File "/usr/local/lib/python3.11/site-packages/urllib3/connection.py", line 507, in getresponse
    httplib_response = super().getresponse()
                       ^^^^^^^^^^^^^^^^^^^^^
  File "/usr/local/lib/python3.11/http/client.py", line 1395, in getresponse
    response.begin()
  File "/usr/local/lib/python3.11/http/client.py", line 325, in begin
    version, status, reason = self._read_status()
                              ^^^^^^^^^^^^^^^^^^^
  File "/usr/local/lib/python3.11/http/client.py", line 294, in _read_status
    raise RemoteDisconnected("Remote end closed connection without"
urllib3.exceptions.ProtocolError: ('Connection aborted.', RemoteDisconnected('Remote end closed connection without response'))

During handling of the above exception, another exception occurred:

Traceback (most recent call last):
  File "/app/src/services/model_sync.py", line 22, in sync_models_with_nn_api
    nn_models_response = nn_client.getAvailableModels()
                         ^^^^^^^^^^^^^^^^^^^^^^^^^^^^^^
  File "/app/src/cloudServices/nnApiConnections.py", line 146, in getAvailableModels
    response = requests.get(url, headers=headers)
               ^^^^^^^^^^^^^^^^^^^^^^^^^^^^^^^^^^
  File "/usr/local/lib/python3.11/site-packages/requests/api.py", line 73, in get
    return request("get", url, params=params, **kwargs)
           ^^^^^^^^^^^^^^^^^^^^^^^^^^^^^^^^^^^^^^^^^^^^
  File "/usr/local/lib/python3.11/site-packages/requests/api.py", line 59, in request
    return session.request(method=method, url=url, **kwargs)
           ^^^^^^^^^^^^^^^^^^^^^^^^^^^^^^^^^^^^^^^^^^^^^^^^^
  File "/usr/local/lib/python3.11/site-packages/requests/sessions.py", line 589, in request
    resp = self.send(prep, **send_kwargs)
           ^^^^^^^^^^^^^^^^^^^^^^^^^^^^^^
  File "/usr/local/lib/python3.11/site-packages/requests/sessions.py", line 703, in send
    r = adapter.send(request, **kwargs)
        ^^^^^^^^^^^^^^^^^^^^^^^^^^^^^^^
  File "/usr/local/lib/python3.11/site-packages/requests/adapters.py", line 682, in send
    raise ConnectionError(err, request=request)
requests.exceptions.ConnectionError: ('Connection aborted.', RemoteDisconnected('Remote end closed connection without response'))
[2025-10-01: 04:47:27] [model_sync] > Error syncing models from NN API: ('Connection aborted.', RemoteDisconnected('Remote end closed connection without response')) >> (<class 'requests.exceptions.ConnectionError'>, ConnectionError(ProtocolError('Connection aborted.', RemoteDisconnected('Remote end closed connection without response'))), <traceback object at 0x7a0a216a3200>)
Traceback (most recent call last):
  File "/usr/local/lib/python3.11/site-packages/urllib3/connectionpool.py", line 789, in urlopen
    response = self._make_request(
               ^^^^^^^^^^^^^^^^^^^
  File "/usr/local/lib/python3.11/site-packages/urllib3/connectionpool.py", line 536, in _make_request
    response = conn.getresponse()
               ^^^^^^^^^^^^^^^^^^
  File "/usr/local/lib/python3.11/site-packages/urllib3/connection.py", line 507, in getresponse
    httplib_response = super().getresponse()
                       ^^^^^^^^^^^^^^^^^^^^^
  File "/usr/local/lib/python3.11/http/client.py", line 1395, in getresponse
    response.begin()
  File "/usr/local/lib/python3.11/http/client.py", line 325, in begin
    version, status, reason = self._read_status()
                              ^^^^^^^^^^^^^^^^^^^
  File "/usr/local/lib/python3.11/http/client.py", line 294, in _read_status
    raise RemoteDisconnected("Remote end closed connection without"
http.client.RemoteDisconnected: Remote end closed connection without response

During handling of the above exception, another exception occurred:

Traceback (most recent call last):
  File "/usr/local/lib/python3.11/site-packages/requests/adapters.py", line 667, in send
    resp = conn.urlopen(
           ^^^^^^^^^^^^^
  File "/usr/local/lib/python3.11/site-packages/urllib3/connectionpool.py", line 843, in urlopen
    retries = retries.increment(
              ^^^^^^^^^^^^^^^^^^
  File "/usr/local/lib/python3.11/site-packages/urllib3/util/retry.py", line 474, in increment
    raise reraise(type(error), error, _stacktrace)
          ^^^^^^^^^^^^^^^^^^^^^^^^^^^^^^^^^^^^^^^^
  File "/usr/local/lib/python3.11/site-packages/urllib3/util/util.py", line 38, in reraise
    raise value.with_traceback(tb)
  File "/usr/local/lib/python3.11/site-packages/urllib3/connectionpool.py", line 789, in urlopen
    response = self._make_request(
               ^^^^^^^^^^^^^^^^^^^
  File "/usr/local/lib/python3.11/site-packages/urllib3/connectionpool.py", line 536, in _make_request
    response = conn.getresponse()
               ^^^^^^^^^^^^^^^^^^
  File "/usr/local/lib/python3.11/site-packages/urllib3/connection.py", line 507, in getresponse
    httplib_response = super().getresponse()
                       ^^^^^^^^^^^^^^^^^^^^^
  File "/usr/local/lib/python3.11/http/client.py", line 1395, in getresponse
    response.begin()
  File "/usr/local/lib/python3.11/http/client.py", line 325, in begin
    version, status, reason = self._read_status()
                              ^^^^^^^^^^^^^^^^^^^
  File "/usr/local/lib/python3.11/http/client.py", line 294, in _read_status
    raise RemoteDisconnected("Remote end closed connection without"
urllib3.exceptions.ProtocolError: ('Connection aborted.', RemoteDisconnected('Remote end closed connection without response'))

During handling of the above exception, another exception occurred:

Traceback (most recent call last):
  File "/app/src/services/model_sync.py", line 22, in sync_models_with_nn_api
    nn_models_response = nn_client.getAvailableModels()
                         ^^^^^^^^^^^^^^^^^^^^^^^^^^^^^^
  File "/app/src/cloudServices/nnApiConnections.py", line 146, in getAvailableModels
    response = requests.get(url, headers=headers)
               ^^^^^^^^^^^^^^^^^^^^^^^^^^^^^^^^^^
  File "/usr/local/lib/python3.11/site-packages/requests/api.py", line 73, in get
    return request("get", url, params=params, **kwargs)
           ^^^^^^^^^^^^^^^^^^^^^^^^^^^^^^^^^^^^^^^^^^^^
  File "/usr/local/lib/python3.11/site-packages/requests/api.py", line 59, in request
    return session.request(method=method, url=url, **kwargs)
           ^^^^^^^^^^^^^^^^^^^^^^^^^^^^^^^^^^^^^^^^^^^^^^^^^
  File "/usr/local/lib/python3.11/site-packages/requests/sessions.py", line 589, in request
    resp = self.send(prep, **send_kwargs)
           ^^^^^^^^^^^^^^^^^^^^^^^^^^^^^^
  File "/usr/local/lib/python3.11/site-packages/requests/sessions.py", line 703, in send
    r = adapter.send(request, **kwargs)
        ^^^^^^^^^^^^^^^^^^^^^^^^^^^^^^^
  File "/usr/local/lib/python3.11/site-packages/requests/adapters.py", line 682, in send
    raise ConnectionError(err, request=request)
requests.exceptions.ConnectionError: ('Connection aborted.', RemoteDisconnected('Remote end closed connection without response'))
