[2025-08-04: 23:57:06] [inferences] > Error generating inference for 06793de5c0634036b22d5b243460f8c2/original_img.jpg >> (<class 'requests.exceptions.HTTPError'>, HTTPError('500 Server Error: INTERNAL SERVER ERROR for url: http://192.168.100.79:8080/inferencia'), <traceback object at 0x7f69a99d76c0>)
Traceback (most recent call last):
  File "/app/src/routes/inferences.py", line 85, in generateInference
    json_response = nnClient.generateInference(payload)
                    ^^^^^^^^^^^^^^^^^^^^^^^^^^^^^^^^^^^
  File "/app/src/cloudServices/nnApiConnections.py", line 44, in generateInference
    response.raise_for_status()
  File "/usr/local/lib/python3.11/site-packages/requests/models.py", line 1024, in raise_for_status
    raise HTTPError(http_error_msg, response=self)
requests.exceptions.HTTPError: 500 Server Error: INTERNAL SERVER ERROR for url: http://192.168.100.79:8080/inferencia
[2025-08-05: 00:07:18] [inferences] > Error generating inference for 2b6550666b0248fb87186a04c597154f/original_img.jpg >> (<class 'requests.exceptions.HTTPError'>, HTTPError('500 Server Error: INTERNAL SERVER ERROR for url: http://192.168.100.79:8080/inferencia'), <traceback object at 0x7f69a99f4380>)
Traceback (most recent call last):
  File "/app/src/routes/inferences.py", line 85, in generateInference
    json_response = nnClient.generateInference(payload)
                    ^^^^^^^^^^^^^^^^^^^^^^^^^^^^^^^^^^^
  File "/app/src/cloudServices/nnApiConnections.py", line 44, in generateInference
    response.raise_for_status()
  File "/usr/local/lib/python3.11/site-packages/requests/models.py", line 1024, in raise_for_status
    raise HTTPError(http_error_msg, response=self)
requests.exceptions.HTTPError: 500 Server Error: INTERNAL SERVER ERROR for url: http://192.168.100.79:8080/inferencia
[2025-08-05: 00:09:59] [inferences] > Error generating inference for 2b6550666b0248fb87186a04c597154f/original_img.jpg >> (<class 'requests.exceptions.HTTPError'>, HTTPError('500 Server Error: INTERNAL SERVER ERROR for url: http://192.168.100.79:8080/inferencia'), <traceback object at 0x7f69a99f51c0>)
Traceback (most recent call last):
  File "/app/src/routes/inferences.py", line 85, in generateInference
    json_response = nnClient.generateInference(payload)
                    ^^^^^^^^^^^^^^^^^^^^^^^^^^^^^^^^^^^
  File "/app/src/cloudServices/nnApiConnections.py", line 44, in generateInference
    response.raise_for_status()
  File "/usr/local/lib/python3.11/site-packages/requests/models.py", line 1024, in raise_for_status
    raise HTTPError(http_error_msg, response=self)
requests.exceptions.HTTPError: 500 Server Error: INTERNAL SERVER ERROR for url: http://192.168.100.79:8080/inferencia
[2025-08-05: 00:21:39] [inferences] > Error generating inference for 2b6550666b0248fb87186a04c597154f/original_img.jpg >> (<class 'requests.exceptions.HTTPError'>, HTTPError('500 Server Error: INTERNAL SERVER ERROR for url: http://192.168.100.79:8080/inferencia'), <traceback object at 0x7f69a99f64c0>)
Traceback (most recent call last):
  File "/app/src/routes/inferences.py", line 85, in generateInference
    json_response = nnClient.generateInference(payload)
                    ^^^^^^^^^^^^^^^^^^^^^^^^^^^^^^^^^^^
  File "/app/src/cloudServices/nnApiConnections.py", line 44, in generateInference
    response.raise_for_status()
  File "/usr/local/lib/python3.11/site-packages/requests/models.py", line 1024, in raise_for_status
    raise HTTPError(http_error_msg, response=self)
requests.exceptions.HTTPError: 500 Server Error: INTERNAL SERVER ERROR for url: http://192.168.100.79:8080/inferencia
[2025-08-05: 01:04:42] [inferences] > Error generating inference for 7e97d891273b4c50a5bae2cdb8b1c771/original_img.jpg >> (<class 'requests.exceptions.HTTPError'>, HTTPError('401 Client Error: UNAUTHORIZED for url: http://192.168.100.79:8080/inferencia'), <traceback object at 0x7f69a88015c0>)
Traceback (most recent call last):
  File "/app/src/routes/inferences.py", line 85, in generateInference
    json_response = nnClient.generateInference(payload)
                    ^^^^^^^^^^^^^^^^^^^^^^^^^^^^^^^^^^^
  File "/app/src/cloudServices/nnApiConnections.py", line 44, in generateInference
    response.raise_for_status()
  File "/usr/local/lib/python3.11/site-packages/requests/models.py", line 1024, in raise_for_status
    raise HTTPError(http_error_msg, response=self)
requests.exceptions.HTTPError: 401 Client Error: UNAUTHORIZED for url: http://192.168.100.79:8080/inferencia
[2025-08-05: 01:06:18] [inferences] > Error generating inference for 9724eff2ab6e4c95b442c182dde77dfe/original_img.jpg >> (<class 'requests.exceptions.HTTPError'>, HTTPError('401 Client Error: UNAUTHORIZED for url: http://192.168.100.79:8080/inferencia'), <traceback object at 0x7f69a99af700>)
Traceback (most recent call last):
  File "/app/src/routes/inferences.py", line 85, in generateInference
    json_response = nnClient.generateInference(payload)
                    ^^^^^^^^^^^^^^^^^^^^^^^^^^^^^^^^^^^
  File "/app/src/cloudServices/nnApiConnections.py", line 44, in generateInference
    response.raise_for_status()
  File "/usr/local/lib/python3.11/site-packages/requests/models.py", line 1024, in raise_for_status
    raise HTTPError(http_error_msg, response=self)
requests.exceptions.HTTPError: 401 Client Error: UNAUTHORIZED for url: http://192.168.100.79:8080/inferencia
[2025-08-05: 01:07:31] [inferences] > Error generating inference for 9724eff2ab6e4c95b442c182dde77dfe/original_img.jpg >> (<class 'requests.exceptions.HTTPError'>, HTTPError('401 Client Error: UNAUTHORIZED for url: http://192.168.100.79:8080/inferencia'), <traceback object at 0x7f69a99d8980>)
Traceback (most recent call last):
  File "/app/src/routes/inferences.py", line 85, in generateInference
    json_response = nnClient.generateInference(payload)
                    ^^^^^^^^^^^^^^^^^^^^^^^^^^^^^^^^^^^
  File "/app/src/cloudServices/nnApiConnections.py", line 44, in generateInference
    response.raise_for_status()
  File "/usr/local/lib/python3.11/site-packages/requests/models.py", line 1024, in raise_for_status
    raise HTTPError(http_error_msg, response=self)
requests.exceptions.HTTPError: 401 Client Error: UNAUTHORIZED for url: http://192.168.100.79:8080/inferencia
[2025-08-05: 01:08:05] [inferences] > Error generating inference for 9724eff2ab6e4c95b442c182dde77dfe/original_img.jpg >> (<class 'requests.exceptions.HTTPError'>, HTTPError('401 Client Error: UNAUTHORIZED for url: http://192.168.100.79:8080/inferencia'), <traceback object at 0x7f69ab56e0c0>)
Traceback (most recent call last):
  File "/app/src/routes/inferences.py", line 85, in generateInference
    json_response = nnClient.generateInference(payload)
                    ^^^^^^^^^^^^^^^^^^^^^^^^^^^^^^^^^^^
  File "/app/src/cloudServices/nnApiConnections.py", line 44, in generateInference
    response.raise_for_status()
  File "/usr/local/lib/python3.11/site-packages/requests/models.py", line 1024, in raise_for_status
    raise HTTPError(http_error_msg, response=self)
requests.exceptions.HTTPError: 401 Client Error: UNAUTHORIZED for url: http://192.168.100.79:8080/inferencia
[2025-08-23: 00:01:54] [inferences] > Presigned S3 error >> (<class 'urllib3.exceptions.MaxRetryError'>, MaxRetryError("HTTPConnectionPool(host='192.168.100.79', port=9000): Max retries exceeded with url: /inferences?location= (Caused by NewConnectionError('<urllib3.connection.HTTPConnection object at 0x7f9e8b857150>: Failed to establish a new connection: [Errno 113] No route to host'))"), <traceback object at 0x7f9e8b8542c0>)
Traceback (most recent call last):
  File "/usr/local/lib/python3.11/site-packages/urllib3/connection.py", line 199, in _new_conn
    sock = connection.create_connection(
           ^^^^^^^^^^^^^^^^^^^^^^^^^^^^^
  File "/usr/local/lib/python3.11/site-packages/urllib3/util/connection.py", line 85, in create_connection
    raise err
  File "/usr/local/lib/python3.11/site-packages/urllib3/util/connection.py", line 73, in create_connection
    sock.connect(sa)
OSError: [Errno 113] No route to host

The above exception was the direct cause of the following exception:

Traceback (most recent call last):
  File "/usr/local/lib/python3.11/site-packages/urllib3/connectionpool.py", line 789, in urlopen
    response = self._make_request(
               ^^^^^^^^^^^^^^^^^^^
  File "/usr/local/lib/python3.11/site-packages/urllib3/connectionpool.py", line 495, in _make_request
    conn.request(
  File "/usr/local/lib/python3.11/site-packages/urllib3/connection.py", line 441, in request
    self.endheaders()
  File "/usr/local/lib/python3.11/http/client.py", line 1298, in endheaders
    self._send_output(message_body, encode_chunked=encode_chunked)
  File "/usr/local/lib/python3.11/http/client.py", line 1058, in _send_output
    self.send(msg)
  File "/usr/local/lib/python3.11/http/client.py", line 996, in send
    self.connect()
  File "/usr/local/lib/python3.11/site-packages/urllib3/connection.py", line 279, in connect
    self.sock = self._new_conn()
                ^^^^^^^^^^^^^^^^
  File "/usr/local/lib/python3.11/site-packages/urllib3/connection.py", line 214, in _new_conn
    raise NewConnectionError(
urllib3.exceptions.NewConnectionError: <urllib3.connection.HTTPConnection object at 0x7f9e8b857150>: Failed to establish a new connection: [Errno 113] No route to host

The above exception was the direct cause of the following exception:

Traceback (most recent call last):
  File "/app/src/routes/inferences.py", line 47, in getBaseImgPresignedUrls
    imgUploadUrl = minioClient.presigned_put_object(
                   ^^^^^^^^^^^^^^^^^^^^^^^^^^^^^^^^^
  File "/usr/local/lib/python3.11/site-packages/minio/api.py", line 2444, in presigned_put_object
    return self.get_presigned_url(
           ^^^^^^^^^^^^^^^^^^^^^^^
  File "/usr/local/lib/python3.11/site-packages/minio/api.py", line 2339, in get_presigned_url
    region = self._get_region(bucket_name)
             ^^^^^^^^^^^^^^^^^^^^^^^^^^^^^
  File "/usr/local/lib/python3.11/site-packages/minio/api.py", line 495, in _get_region
    response = self._url_open(
               ^^^^^^^^^^^^^^^
  File "/usr/local/lib/python3.11/site-packages/minio/api.py", line 303, in _url_open
    response = self._http.urlopen(
               ^^^^^^^^^^^^^^^^^^^
  File "/usr/local/lib/python3.11/site-packages/urllib3/poolmanager.py", line 443, in urlopen
    response = conn.urlopen(method, u.request_uri, **kw)
               ^^^^^^^^^^^^^^^^^^^^^^^^^^^^^^^^^^^^^^^^^
  File "/usr/local/lib/python3.11/site-packages/urllib3/connectionpool.py", line 873, in urlopen
    return self.urlopen(
           ^^^^^^^^^^^^^
  File "/usr/local/lib/python3.11/site-packages/urllib3/connectionpool.py", line 873, in urlopen
    return self.urlopen(
           ^^^^^^^^^^^^^
  File "/usr/local/lib/python3.11/site-packages/urllib3/connectionpool.py", line 873, in urlopen
    return self.urlopen(
           ^^^^^^^^^^^^^
  [Previous line repeated 2 more times]
  File "/usr/local/lib/python3.11/site-packages/urllib3/connectionpool.py", line 843, in urlopen
    retries = retries.increment(
              ^^^^^^^^^^^^^^^^^^
  File "/usr/local/lib/python3.11/site-packages/urllib3/util/retry.py", line 519, in increment
    raise MaxRetryError(_pool, url, reason) from reason  # type: ignore[arg-type]
    ^^^^^^^^^^^^^^^^^^^^^^^^^^^^^^^^^^^^^^^^^^^^^^^^^^^
urllib3.exceptions.MaxRetryError: HTTPConnectionPool(host='192.168.100.79', port=9000): Max retries exceeded with url: /inferences?location= (Caused by NewConnectionError('<urllib3.connection.HTTPConnection object at 0x7f9e8b857150>: Failed to establish a new connection: [Errno 113] No route to host'))
[2025-08-23: 04:50:24] [inferences] > Error generating inference for e7e36ab0c62648978b61ca4346dae31d/original_img.jpg >> (<class 'requests.exceptions.HTTPError'>, HTTPError('404 Client Error: Not Found for url: http://192.168.100.80:8080/inferencia'), <traceback object at 0x7fe448c81080>)
Traceback (most recent call last):
  File "/app/src/routes/inferences.py", line 85, in generateInference
    json_response = nnClient.generateInference(payload)
                    ^^^^^^^^^^^^^^^^^^^^^^^^^^^^^^^^^^^
  File "/app/src/cloudServices/nnApiConnections.py", line 44, in generateInference
    response.raise_for_status()
  File "/usr/local/lib/python3.11/site-packages/requests/models.py", line 1024, in raise_for_status
    raise HTTPError(http_error_msg, response=self)
requests.exceptions.HTTPError: 404 Client Error: Not Found for url: http://192.168.100.80:8080/inferencia
[2025-08-23: 04:51:23] [inferences] > Error generating inference for e7e36ab0c62648978b61ca4346dae31d/original_img.jpg >> (<class 'requests.exceptions.HTTPError'>, HTTPError('404 Client Error: Not Found for url: http://192.168.100.80:8080/inferencia'), <traceback object at 0x7fe4488d91c0>)
Traceback (most recent call last):
  File "/app/src/routes/inferences.py", line 85, in generateInference
    json_response = nnClient.generateInference(payload)
                    ^^^^^^^^^^^^^^^^^^^^^^^^^^^^^^^^^^^
  File "/app/src/cloudServices/nnApiConnections.py", line 44, in generateInference
    response.raise_for_status()
  File "/usr/local/lib/python3.11/site-packages/requests/models.py", line 1024, in raise_for_status
    raise HTTPError(http_error_msg, response=self)
requests.exceptions.HTTPError: 404 Client Error: Not Found for url: http://192.168.100.80:8080/inferencia
[2025-08-23: 06:39:31] [inferences] > Error generating inference for bd816cda2b4743b79e09dbdac742807b/original_img.jpg >> (<class 'requests.exceptions.HTTPError'>, HTTPError('500 Server Error: Internal Server Error for url: http://192.168.100.80:8080/inferencia'), <traceback object at 0x7f6a34435e00>)
Traceback (most recent call last):
  File "/app/src/routes/inferences.py", line 85, in generateInference
    json_response = nnClient.generateInference(payload)
                    ^^^^^^^^^^^^^^^^^^^^^^^^^^^^^^^^^^^
  File "/app/src/cloudServices/nnApiConnections.py", line 44, in generateInference
    response.raise_for_status()
  File "/usr/local/lib/python3.11/site-packages/requests/models.py", line 1024, in raise_for_status
    raise HTTPError(http_error_msg, response=self)
requests.exceptions.HTTPError: 500 Server Error: Internal Server Error for url: http://192.168.100.80:8080/inferencia
