[2025-08-04: 23:57:06] [inferences] > Error generating inference for 06793de5c0634036b22d5b243460f8c2/original_img.jpg >> (<class 'requests.exceptions.HTTPError'>, HTTPError('500 Server Error: INTERNAL SERVER ERROR for url: http://192.168.100.79:8080/inferencia'), <traceback object at 0x7f69a99d76c0>)
Traceback (most recent call last):
  File "/app/src/routes/inferences.py", line 85, in generateInference
    json_response = nnClient.generateInference(payload)
                    ^^^^^^^^^^^^^^^^^^^^^^^^^^^^^^^^^^^
  File "/app/src/cloudServices/nnApiConnections.py", line 44, in generateInference
    response.raise_for_status()
  File "/usr/local/lib/python3.11/site-packages/requests/models.py", line 1024, in raise_for_status
    raise HTTPError(http_error_msg, response=self)
requests.exceptions.HTTPError: 500 Server Error: INTERNAL SERVER ERROR for url: http://192.168.100.79:8080/inferencia
[2025-08-05: 00:07:18] [inferences] > Error generating inference for 2b6550666b0248fb87186a04c597154f/original_img.jpg >> (<class 'requests.exceptions.HTTPError'>, HTTPError('500 Server Error: INTERNAL SERVER ERROR for url: http://192.168.100.79:8080/inferencia'), <traceback object at 0x7f69a99f4380>)
Traceback (most recent call last):
  File "/app/src/routes/inferences.py", line 85, in generateInference
    json_response = nnClient.generateInference(payload)
                    ^^^^^^^^^^^^^^^^^^^^^^^^^^^^^^^^^^^
  File "/app/src/cloudServices/nnApiConnections.py", line 44, in generateInference
    response.raise_for_status()
  File "/usr/local/lib/python3.11/site-packages/requests/models.py", line 1024, in raise_for_status
    raise HTTPError(http_error_msg, response=self)
requests.exceptions.HTTPError: 500 Server Error: INTERNAL SERVER ERROR for url: http://192.168.100.79:8080/inferencia
[2025-08-05: 00:09:59] [inferences] > Error generating inference for 2b6550666b0248fb87186a04c597154f/original_img.jpg >> (<class 'requests.exceptions.HTTPError'>, HTTPError('500 Server Error: INTERNAL SERVER ERROR for url: http://192.168.100.79:8080/inferencia'), <traceback object at 0x7f69a99f51c0>)
Traceback (most recent call last):
  File "/app/src/routes/inferences.py", line 85, in generateInference
    json_response = nnClient.generateInference(payload)
                    ^^^^^^^^^^^^^^^^^^^^^^^^^^^^^^^^^^^
  File "/app/src/cloudServices/nnApiConnections.py", line 44, in generateInference
    response.raise_for_status()
  File "/usr/local/lib/python3.11/site-packages/requests/models.py", line 1024, in raise_for_status
    raise HTTPError(http_error_msg, response=self)
requests.exceptions.HTTPError: 500 Server Error: INTERNAL SERVER ERROR for url: http://192.168.100.79:8080/inferencia
[2025-08-05: 00:21:39] [inferences] > Error generating inference for 2b6550666b0248fb87186a04c597154f/original_img.jpg >> (<class 'requests.exceptions.HTTPError'>, HTTPError('500 Server Error: INTERNAL SERVER ERROR for url: http://192.168.100.79:8080/inferencia'), <traceback object at 0x7f69a99f64c0>)
Traceback (most recent call last):
  File "/app/src/routes/inferences.py", line 85, in generateInference
    json_response = nnClient.generateInference(payload)
                    ^^^^^^^^^^^^^^^^^^^^^^^^^^^^^^^^^^^
  File "/app/src/cloudServices/nnApiConnections.py", line 44, in generateInference
    response.raise_for_status()
  File "/usr/local/lib/python3.11/site-packages/requests/models.py", line 1024, in raise_for_status
    raise HTTPError(http_error_msg, response=self)
requests.exceptions.HTTPError: 500 Server Error: INTERNAL SERVER ERROR for url: http://192.168.100.79:8080/inferencia
[2025-08-05: 01:04:42] [inferences] > Error generating inference for 7e97d891273b4c50a5bae2cdb8b1c771/original_img.jpg >> (<class 'requests.exceptions.HTTPError'>, HTTPError('401 Client Error: UNAUTHORIZED for url: http://192.168.100.79:8080/inferencia'), <traceback object at 0x7f69a88015c0>)
Traceback (most recent call last):
  File "/app/src/routes/inferences.py", line 85, in generateInference
    json_response = nnClient.generateInference(payload)
                    ^^^^^^^^^^^^^^^^^^^^^^^^^^^^^^^^^^^
  File "/app/src/cloudServices/nnApiConnections.py", line 44, in generateInference
    response.raise_for_status()
  File "/usr/local/lib/python3.11/site-packages/requests/models.py", line 1024, in raise_for_status
    raise HTTPError(http_error_msg, response=self)
requests.exceptions.HTTPError: 401 Client Error: UNAUTHORIZED for url: http://192.168.100.79:8080/inferencia
[2025-08-05: 01:06:18] [inferences] > Error generating inference for 9724eff2ab6e4c95b442c182dde77dfe/original_img.jpg >> (<class 'requests.exceptions.HTTPError'>, HTTPError('401 Client Error: UNAUTHORIZED for url: http://192.168.100.79:8080/inferencia'), <traceback object at 0x7f69a99af700>)
Traceback (most recent call last):
  File "/app/src/routes/inferences.py", line 85, in generateInference
    json_response = nnClient.generateInference(payload)
                    ^^^^^^^^^^^^^^^^^^^^^^^^^^^^^^^^^^^
  File "/app/src/cloudServices/nnApiConnections.py", line 44, in generateInference
    response.raise_for_status()
  File "/usr/local/lib/python3.11/site-packages/requests/models.py", line 1024, in raise_for_status
    raise HTTPError(http_error_msg, response=self)
requests.exceptions.HTTPError: 401 Client Error: UNAUTHORIZED for url: http://192.168.100.79:8080/inferencia
[2025-08-05: 01:07:31] [inferences] > Error generating inference for 9724eff2ab6e4c95b442c182dde77dfe/original_img.jpg >> (<class 'requests.exceptions.HTTPError'>, HTTPError('401 Client Error: UNAUTHORIZED for url: http://192.168.100.79:8080/inferencia'), <traceback object at 0x7f69a99d8980>)
Traceback (most recent call last):
  File "/app/src/routes/inferences.py", line 85, in generateInference
    json_response = nnClient.generateInference(payload)
                    ^^^^^^^^^^^^^^^^^^^^^^^^^^^^^^^^^^^
  File "/app/src/cloudServices/nnApiConnections.py", line 44, in generateInference
    response.raise_for_status()
  File "/usr/local/lib/python3.11/site-packages/requests/models.py", line 1024, in raise_for_status
    raise HTTPError(http_error_msg, response=self)
requests.exceptions.HTTPError: 401 Client Error: UNAUTHORIZED for url: http://192.168.100.79:8080/inferencia
[2025-08-05: 01:08:05] [inferences] > Error generating inference for 9724eff2ab6e4c95b442c182dde77dfe/original_img.jpg >> (<class 'requests.exceptions.HTTPError'>, HTTPError('401 Client Error: UNAUTHORIZED for url: http://192.168.100.79:8080/inferencia'), <traceback object at 0x7f69ab56e0c0>)
Traceback (most recent call last):
  File "/app/src/routes/inferences.py", line 85, in generateInference
    json_response = nnClient.generateInference(payload)
                    ^^^^^^^^^^^^^^^^^^^^^^^^^^^^^^^^^^^
  File "/app/src/cloudServices/nnApiConnections.py", line 44, in generateInference
    response.raise_for_status()
  File "/usr/local/lib/python3.11/site-packages/requests/models.py", line 1024, in raise_for_status
    raise HTTPError(http_error_msg, response=self)
requests.exceptions.HTTPError: 401 Client Error: UNAUTHORIZED for url: http://192.168.100.79:8080/inferencia
[2025-08-23: 00:01:54] [inferences] > Presigned S3 error >> (<class 'urllib3.exceptions.MaxRetryError'>, MaxRetryError("HTTPConnectionPool(host='192.168.100.79', port=9000): Max retries exceeded with url: /inferences?location= (Caused by NewConnectionError('<urllib3.connection.HTTPConnection object at 0x7f9e8b857150>: Failed to establish a new connection: [Errno 113] No route to host'))"), <traceback object at 0x7f9e8b8542c0>)
Traceback (most recent call last):
  File "/usr/local/lib/python3.11/site-packages/urllib3/connection.py", line 199, in _new_conn
    sock = connection.create_connection(
           ^^^^^^^^^^^^^^^^^^^^^^^^^^^^^
  File "/usr/local/lib/python3.11/site-packages/urllib3/util/connection.py", line 85, in create_connection
    raise err
  File "/usr/local/lib/python3.11/site-packages/urllib3/util/connection.py", line 73, in create_connection
    sock.connect(sa)
OSError: [Errno 113] No route to host

The above exception was the direct cause of the following exception:

Traceback (most recent call last):
  File "/usr/local/lib/python3.11/site-packages/urllib3/connectionpool.py", line 789, in urlopen
    response = self._make_request(
               ^^^^^^^^^^^^^^^^^^^
  File "/usr/local/lib/python3.11/site-packages/urllib3/connectionpool.py", line 495, in _make_request
    conn.request(
  File "/usr/local/lib/python3.11/site-packages/urllib3/connection.py", line 441, in request
    self.endheaders()
  File "/usr/local/lib/python3.11/http/client.py", line 1298, in endheaders
    self._send_output(message_body, encode_chunked=encode_chunked)
  File "/usr/local/lib/python3.11/http/client.py", line 1058, in _send_output
    self.send(msg)
  File "/usr/local/lib/python3.11/http/client.py", line 996, in send
    self.connect()
  File "/usr/local/lib/python3.11/site-packages/urllib3/connection.py", line 279, in connect
    self.sock = self._new_conn()
                ^^^^^^^^^^^^^^^^
  File "/usr/local/lib/python3.11/site-packages/urllib3/connection.py", line 214, in _new_conn
    raise NewConnectionError(
urllib3.exceptions.NewConnectionError: <urllib3.connection.HTTPConnection object at 0x7f9e8b857150>: Failed to establish a new connection: [Errno 113] No route to host

The above exception was the direct cause of the following exception:

Traceback (most recent call last):
  File "/app/src/routes/inferences.py", line 47, in getBaseImgPresignedUrls
    imgUploadUrl = minioClient.presigned_put_object(
                   ^^^^^^^^^^^^^^^^^^^^^^^^^^^^^^^^^
  File "/usr/local/lib/python3.11/site-packages/minio/api.py", line 2444, in presigned_put_object
    return self.get_presigned_url(
           ^^^^^^^^^^^^^^^^^^^^^^^
  File "/usr/local/lib/python3.11/site-packages/minio/api.py", line 2339, in get_presigned_url
    region = self._get_region(bucket_name)
             ^^^^^^^^^^^^^^^^^^^^^^^^^^^^^
  File "/usr/local/lib/python3.11/site-packages/minio/api.py", line 495, in _get_region
    response = self._url_open(
               ^^^^^^^^^^^^^^^
  File "/usr/local/lib/python3.11/site-packages/minio/api.py", line 303, in _url_open
    response = self._http.urlopen(
               ^^^^^^^^^^^^^^^^^^^
  File "/usr/local/lib/python3.11/site-packages/urllib3/poolmanager.py", line 443, in urlopen
    response = conn.urlopen(method, u.request_uri, **kw)
               ^^^^^^^^^^^^^^^^^^^^^^^^^^^^^^^^^^^^^^^^^
  File "/usr/local/lib/python3.11/site-packages/urllib3/connectionpool.py", line 873, in urlopen
    return self.urlopen(
           ^^^^^^^^^^^^^
  File "/usr/local/lib/python3.11/site-packages/urllib3/connectionpool.py", line 873, in urlopen
    return self.urlopen(
           ^^^^^^^^^^^^^
  File "/usr/local/lib/python3.11/site-packages/urllib3/connectionpool.py", line 873, in urlopen
    return self.urlopen(
           ^^^^^^^^^^^^^
  [Previous line repeated 2 more times]
  File "/usr/local/lib/python3.11/site-packages/urllib3/connectionpool.py", line 843, in urlopen
    retries = retries.increment(
              ^^^^^^^^^^^^^^^^^^
  File "/usr/local/lib/python3.11/site-packages/urllib3/util/retry.py", line 519, in increment
    raise MaxRetryError(_pool, url, reason) from reason  # type: ignore[arg-type]
    ^^^^^^^^^^^^^^^^^^^^^^^^^^^^^^^^^^^^^^^^^^^^^^^^^^^
urllib3.exceptions.MaxRetryError: HTTPConnectionPool(host='192.168.100.79', port=9000): Max retries exceeded with url: /inferences?location= (Caused by NewConnectionError('<urllib3.connection.HTTPConnection object at 0x7f9e8b857150>: Failed to establish a new connection: [Errno 113] No route to host'))
[2025-08-23: 04:50:24] [inferences] > Error generating inference for e7e36ab0c62648978b61ca4346dae31d/original_img.jpg >> (<class 'requests.exceptions.HTTPError'>, HTTPError('404 Client Error: Not Found for url: http://192.168.100.80:8080/inferencia'), <traceback object at 0x7fe448c81080>)
Traceback (most recent call last):
  File "/app/src/routes/inferences.py", line 85, in generateInference
    json_response = nnClient.generateInference(payload)
                    ^^^^^^^^^^^^^^^^^^^^^^^^^^^^^^^^^^^
  File "/app/src/cloudServices/nnApiConnections.py", line 44, in generateInference
    response.raise_for_status()
  File "/usr/local/lib/python3.11/site-packages/requests/models.py", line 1024, in raise_for_status
    raise HTTPError(http_error_msg, response=self)
requests.exceptions.HTTPError: 404 Client Error: Not Found for url: http://192.168.100.80:8080/inferencia
[2025-08-23: 04:51:23] [inferences] > Error generating inference for e7e36ab0c62648978b61ca4346dae31d/original_img.jpg >> (<class 'requests.exceptions.HTTPError'>, HTTPError('404 Client Error: Not Found for url: http://192.168.100.80:8080/inferencia'), <traceback object at 0x7fe4488d91c0>)
Traceback (most recent call last):
  File "/app/src/routes/inferences.py", line 85, in generateInference
    json_response = nnClient.generateInference(payload)
                    ^^^^^^^^^^^^^^^^^^^^^^^^^^^^^^^^^^^
  File "/app/src/cloudServices/nnApiConnections.py", line 44, in generateInference
    response.raise_for_status()
  File "/usr/local/lib/python3.11/site-packages/requests/models.py", line 1024, in raise_for_status
    raise HTTPError(http_error_msg, response=self)
requests.exceptions.HTTPError: 404 Client Error: Not Found for url: http://192.168.100.80:8080/inferencia
[2025-08-23: 06:39:31] [inferences] > Error generating inference for bd816cda2b4743b79e09dbdac742807b/original_img.jpg >> (<class 'requests.exceptions.HTTPError'>, HTTPError('500 Server Error: Internal Server Error for url: http://192.168.100.80:8080/inferencia'), <traceback object at 0x7f6a34435e00>)
Traceback (most recent call last):
  File "/app/src/routes/inferences.py", line 85, in generateInference
    json_response = nnClient.generateInference(payload)
                    ^^^^^^^^^^^^^^^^^^^^^^^^^^^^^^^^^^^
  File "/app/src/cloudServices/nnApiConnections.py", line 44, in generateInference
    response.raise_for_status()
  File "/usr/local/lib/python3.11/site-packages/requests/models.py", line 1024, in raise_for_status
    raise HTTPError(http_error_msg, response=self)
requests.exceptions.HTTPError: 500 Server Error: Internal Server Error for url: http://192.168.100.80:8080/inferencia
[2025-08-26: 21:22:33] [error_handler] > Unexpected error occurred >> (<class 'TypeError'>, TypeError("rate_limit_login.<locals>.decorator() missing 1 required positional argument: 'f'"), <traceback object at 0x7f5c4d3f5cc0>)
Traceback (most recent call last):
  File "/usr/local/lib/python3.11/site-packages/flask/app.py", line 867, in full_dispatch_request
    rv = self.dispatch_request()
         ^^^^^^^^^^^^^^^^^^^^^^^
  File "/usr/local/lib/python3.11/site-packages/flask/app.py", line 852, in dispatch_request
    return self.ensure_sync(self.view_functions[rule.endpoint])(**view_args)
           ^^^^^^^^^^^^^^^^^^^^^^^^^^^^^^^^^^^^^^^^^^^^^^^^^^^^^^^^^^^^^^^^^
TypeError: rate_limit_login.<locals>.decorator() missing 1 required positional argument: 'f'
[2025-08-26: 21:22:33] [error_handler] > Server error occurred >> None
[2025-08-26: 21:37:31] [auth] > Error generating CSRF token >> (<class 'RuntimeError'>, RuntimeError('The session is unavailable because no secret key was set.  Set the secret_key on the application to something unique and secret.'), <traceback object at 0x7fb8aa664100>)
Traceback (most recent call last):
  File "/app/src/routes/auth.py", line 255, in get_csrf_token_endpoint
    token = get_csrf_token()
            ^^^^^^^^^^^^^^^^
  File "/app/src/security/csrf_protection.py", line 164, in get_csrf_token
    return csrf.generate_csrf_token()
           ^^^^^^^^^^^^^^^^^^^^^^^^^^
  File "/app/src/security/csrf_protection.py", line 129, in generate_csrf_token
    session['_csrf_session_id'] = session_id
    ~~~~~~~^^^^^^^^^^^^^^^^^^^^
  File "/usr/local/lib/python3.11/site-packages/flask/sessions.py", line 97, in _fail
    raise RuntimeError(
RuntimeError: The session is unavailable because no secret key was set.  Set the secret_key on the application to something unique and secret.
[2025-08-26: 21:38:05] [auth] > Error generating CSRF token >> (<class 'RuntimeError'>, RuntimeError('The session is unavailable because no secret key was set.  Set the secret_key on the application to something unique and secret.'), <traceback object at 0x7fb8a9337380>)
Traceback (most recent call last):
  File "/app/src/routes/auth.py", line 255, in get_csrf_token_endpoint
    token = get_csrf_token()
            ^^^^^^^^^^^^^^^^
  File "/app/src/security/csrf_protection.py", line 164, in get_csrf_token
    return csrf.generate_csrf_token()
           ^^^^^^^^^^^^^^^^^^^^^^^^^^
  File "/app/src/security/csrf_protection.py", line 129, in generate_csrf_token
    session['_csrf_session_id'] = session_id
    ~~~~~~~^^^^^^^^^^^^^^^^^^^^
  File "/usr/local/lib/python3.11/site-packages/flask/sessions.py", line 97, in _fail
    raise RuntimeError(
RuntimeError: The session is unavailable because no secret key was set.  Set the secret_key on the application to something unique and secret.
[2025-08-26: 21:40:11] [auth] > Error generating CSRF token >> (<class 'RuntimeError'>, RuntimeError('The session is unavailable because no secret key was set.  Set the secret_key on the application to something unique and secret.'), <traceback object at 0x7fbba58719c0>)
Traceback (most recent call last):
  File "/app/src/routes/auth.py", line 255, in get_csrf_token_endpoint
    token = get_csrf_token()
            ^^^^^^^^^^^^^^^^
  File "/app/src/security/csrf_protection.py", line 164, in get_csrf_token
    return csrf.generate_csrf_token()
           ^^^^^^^^^^^^^^^^^^^^^^^^^^
  File "/app/src/security/csrf_protection.py", line 129, in generate_csrf_token
    session['_csrf_session_id'] = session_id
    ~~~~~~~^^^^^^^^^^^^^^^^^^^^
  File "/usr/local/lib/python3.11/site-packages/flask/sessions.py", line 97, in _fail
    raise RuntimeError(
RuntimeError: The session is unavailable because no secret key was set.  Set the secret_key on the application to something unique and secret.
[2025-08-26: 21:40:30] [auth] > Error generating CSRF token >> (<class 'RuntimeError'>, RuntimeError('The session is unavailable because no secret key was set.  Set the secret_key on the application to something unique and secret.'), <traceback object at 0x7fbba45612c0>)
Traceback (most recent call last):
  File "/app/src/routes/auth.py", line 255, in get_csrf_token_endpoint
    token = get_csrf_token()
            ^^^^^^^^^^^^^^^^
  File "/app/src/security/csrf_protection.py", line 164, in get_csrf_token
    return csrf.generate_csrf_token()
           ^^^^^^^^^^^^^^^^^^^^^^^^^^
  File "/app/src/security/csrf_protection.py", line 129, in generate_csrf_token
    session['_csrf_session_id'] = session_id
    ~~~~~~~^^^^^^^^^^^^^^^^^^^^
  File "/usr/local/lib/python3.11/site-packages/flask/sessions.py", line 97, in _fail
    raise RuntimeError(
RuntimeError: The session is unavailable because no secret key was set.  Set the secret_key on the application to something unique and secret.
[2025-08-26: 21:46:30] [auth] > Error generating CSRF token >> (<class 'RuntimeError'>, RuntimeError('The session is unavailable because no secret key was set.  Set the secret_key on the application to something unique and secret.'), <traceback object at 0x7fa33fd3eac0>)
Traceback (most recent call last):
  File "/app/src/routes/auth.py", line 255, in get_csrf_token_endpoint
    token = get_csrf_token()
            ^^^^^^^^^^^^^^^^
  File "/app/src/security/csrf_protection.py", line 164, in get_csrf_token
    return csrf.generate_csrf_token()
           ^^^^^^^^^^^^^^^^^^^^^^^^^^
  File "/app/src/security/csrf_protection.py", line 129, in generate_csrf_token
    session['_csrf_session_id'] = session_id
    ~~~~~~~^^^^^^^^^^^^^^^^^^^^
  File "/usr/local/lib/python3.11/site-packages/flask/sessions.py", line 97, in _fail
    raise RuntimeError(
RuntimeError: The session is unavailable because no secret key was set.  Set the secret_key on the application to something unique and secret.
[2025-08-26: 22:30:49] [auth] > Default role AI_USER not found >> None
[2025-08-26: 22:30:49] [auth] > Error finding default role during registration >> (<class 'werkzeug.exceptions.InternalServerError'>, <InternalServerError '500: Internal Server Error'>, <traceback object at 0x7f842d26f700>)
Traceback (most recent call last):
  File "/app/src/routes/auth.py", line 119, in register
    abort(500, 'Registration failed - invalid role configuration')
  File "/usr/local/lib/python3.11/site-packages/flask/helpers.py", line 274, in abort
    current_app.aborter(code, *args, **kwargs)
  File "/usr/local/lib/python3.11/site-packages/werkzeug/exceptions.py", line 861, in __call__
    raise self.mapping[code](*args, **kwargs)
werkzeug.exceptions.InternalServerError: 500 Internal Server Error: Registration failed - invalid role configuration
[2025-08-29: 01:22:37] [inferences] > Error saving in DB inference of 1/e00b204e149f43509e4cb6634121e3b0/original_img.jpg >> (<class 'sqlalchemy.exc.NoReferencedTableError'>, NoReferencedTableError("Foreign key associated with column 'inferences.modelId' could not find table 'models' with which to generate a foreign key to target column 'id'"), <traceback object at 0x7f33d256db40>)
Traceback (most recent call last):
  File "/app/src/routes/inferences.py", line 155, in generateInference
    db.session.commit()
  File "/usr/local/lib/python3.11/site-packages/sqlalchemy/orm/scoping.py", line 597, in commit
    return self._proxied.commit()
           ^^^^^^^^^^^^^^^^^^^^^^
  File "/usr/local/lib/python3.11/site-packages/sqlalchemy/orm/session.py", line 2017, in commit
    trans.commit(_to_root=True)
  File "<string>", line 2, in commit
  File "/usr/local/lib/python3.11/site-packages/sqlalchemy/orm/state_changes.py", line 139, in _go
    ret_value = fn(self, *arg, **kw)
                ^^^^^^^^^^^^^^^^^^^^
  File "/usr/local/lib/python3.11/site-packages/sqlalchemy/orm/session.py", line 1302, in commit
    self._prepare_impl()
  File "<string>", line 2, in _prepare_impl
  File "/usr/local/lib/python3.11/site-packages/sqlalchemy/orm/state_changes.py", line 139, in _go
    ret_value = fn(self, *arg, **kw)
                ^^^^^^^^^^^^^^^^^^^^
  File "/usr/local/lib/python3.11/site-packages/sqlalchemy/orm/session.py", line 1277, in _prepare_impl
    self.session.flush()
  File "/usr/local/lib/python3.11/site-packages/sqlalchemy/orm/session.py", line 4341, in flush
    self._flush(objects)
  File "/usr/local/lib/python3.11/site-packages/sqlalchemy/orm/session.py", line 4476, in _flush
    with util.safe_reraise():
  File "/usr/local/lib/python3.11/site-packages/sqlalchemy/util/langhelpers.py", line 146, in __exit__
    raise exc_value.with_traceback(exc_tb)
  File "/usr/local/lib/python3.11/site-packages/sqlalchemy/orm/session.py", line 4437, in _flush
    flush_context.execute()
  File "/usr/local/lib/python3.11/site-packages/sqlalchemy/orm/unitofwork.py", line 466, in execute
    rec.execute(self)
  File "/usr/local/lib/python3.11/site-packages/sqlalchemy/orm/unitofwork.py", line 642, in execute
    util.preloaded.orm_persistence.save_obj(
  File "/usr/local/lib/python3.11/site-packages/sqlalchemy/orm/persistence.py", line 76, in save_obj
    for table, mapper in base_mapper._sorted_tables.items():
                         ^^^^^^^^^^^^^^^^^^^^^^^^^^
  File "/usr/local/lib/python3.11/site-packages/sqlalchemy/util/langhelpers.py", line 1253, in __get__
    obj.__dict__[self.__name__] = result = self.fget(obj)
                                           ^^^^^^^^^^^^^^
  File "/usr/local/lib/python3.11/site-packages/sqlalchemy/orm/mapper.py", line 4050, in _sorted_tables
    sorted_ = sql_util.sort_tables(
              ^^^^^^^^^^^^^^^^^^^^^
  File "/usr/local/lib/python3.11/site-packages/sqlalchemy/sql/ddl.py", line 1252, in sort_tables
    for (t, fkcs) in sort_tables_and_constraints(
                     ^^^^^^^^^^^^^^^^^^^^^^^^^^^^
  File "/usr/local/lib/python3.11/site-packages/sqlalchemy/sql/ddl.py", line 1322, in sort_tables_and_constraints
    filtered = filter_fn(fkc)
               ^^^^^^^^^^^^^^
  File "/usr/local/lib/python3.11/site-packages/sqlalchemy/sql/ddl.py", line 1242, in _skip_fn
    if fixed_skip_fn(fk):
       ^^^^^^^^^^^^^^^^^
  File "/usr/local/lib/python3.11/site-packages/sqlalchemy/orm/mapper.py", line 4033, in skip
    dep = table_to_mapper.get(fk.column.table)
                              ^^^^^^^^^
  File "/usr/local/lib/python3.11/site-packages/sqlalchemy/util/langhelpers.py", line 1141, in __get__
    obj.__dict__[self.__name__] = result = self.fget(obj)
                                           ^^^^^^^^^^^^^^
  File "/usr/local/lib/python3.11/site-packages/sqlalchemy/sql/schema.py", line 3159, in column
    return self._resolve_column()
           ^^^^^^^^^^^^^^^^^^^^^^
  File "/usr/local/lib/python3.11/site-packages/sqlalchemy/sql/schema.py", line 3182, in _resolve_column
    raise exc.NoReferencedTableError(
sqlalchemy.exc.NoReferencedTableError: Foreign key associated with column 'inferences.modelId' could not find table 'models' with which to generate a foreign key to target column 'id'
[2025-08-29: 01:29:28] [inferences] > Error saving in DB inference of 1/ba945f0e69564b4a917b6ebe26c68999/original_img.jpg >> (<class 'sqlalchemy.exc.NoReferencedTableError'>, NoReferencedTableError("Foreign key associated with column 'inferences.modelId' could not find table 'models' with which to generate a foreign key to target column 'id'"), <traceback object at 0x7f2f377034c0>)
Traceback (most recent call last):
  File "/app/src/routes/inferences.py", line 155, in generateInference
    db.session.commit()
  File "/usr/local/lib/python3.11/site-packages/sqlalchemy/orm/scoping.py", line 597, in commit
    return self._proxied.commit()
           ^^^^^^^^^^^^^^^^^^^^^^
  File "/usr/local/lib/python3.11/site-packages/sqlalchemy/orm/session.py", line 2017, in commit
    trans.commit(_to_root=True)
  File "<string>", line 2, in commit
  File "/usr/local/lib/python3.11/site-packages/sqlalchemy/orm/state_changes.py", line 139, in _go
    ret_value = fn(self, *arg, **kw)
                ^^^^^^^^^^^^^^^^^^^^
  File "/usr/local/lib/python3.11/site-packages/sqlalchemy/orm/session.py", line 1302, in commit
    self._prepare_impl()
  File "<string>", line 2, in _prepare_impl
  File "/usr/local/lib/python3.11/site-packages/sqlalchemy/orm/state_changes.py", line 139, in _go
    ret_value = fn(self, *arg, **kw)
                ^^^^^^^^^^^^^^^^^^^^
  File "/usr/local/lib/python3.11/site-packages/sqlalchemy/orm/session.py", line 1277, in _prepare_impl
    self.session.flush()
  File "/usr/local/lib/python3.11/site-packages/sqlalchemy/orm/session.py", line 4341, in flush
    self._flush(objects)
  File "/usr/local/lib/python3.11/site-packages/sqlalchemy/orm/session.py", line 4476, in _flush
    with util.safe_reraise():
  File "/usr/local/lib/python3.11/site-packages/sqlalchemy/util/langhelpers.py", line 146, in __exit__
    raise exc_value.with_traceback(exc_tb)
  File "/usr/local/lib/python3.11/site-packages/sqlalchemy/orm/session.py", line 4437, in _flush
    flush_context.execute()
  File "/usr/local/lib/python3.11/site-packages/sqlalchemy/orm/unitofwork.py", line 466, in execute
    rec.execute(self)
  File "/usr/local/lib/python3.11/site-packages/sqlalchemy/orm/unitofwork.py", line 642, in execute
    util.preloaded.orm_persistence.save_obj(
  File "/usr/local/lib/python3.11/site-packages/sqlalchemy/orm/persistence.py", line 76, in save_obj
    for table, mapper in base_mapper._sorted_tables.items():
                         ^^^^^^^^^^^^^^^^^^^^^^^^^^
  File "/usr/local/lib/python3.11/site-packages/sqlalchemy/util/langhelpers.py", line 1253, in __get__
    obj.__dict__[self.__name__] = result = self.fget(obj)
                                           ^^^^^^^^^^^^^^
  File "/usr/local/lib/python3.11/site-packages/sqlalchemy/orm/mapper.py", line 4050, in _sorted_tables
    sorted_ = sql_util.sort_tables(
              ^^^^^^^^^^^^^^^^^^^^^
  File "/usr/local/lib/python3.11/site-packages/sqlalchemy/sql/ddl.py", line 1252, in sort_tables
    for (t, fkcs) in sort_tables_and_constraints(
                     ^^^^^^^^^^^^^^^^^^^^^^^^^^^^
  File "/usr/local/lib/python3.11/site-packages/sqlalchemy/sql/ddl.py", line 1322, in sort_tables_and_constraints
    filtered = filter_fn(fkc)
               ^^^^^^^^^^^^^^
  File "/usr/local/lib/python3.11/site-packages/sqlalchemy/sql/ddl.py", line 1242, in _skip_fn
    if fixed_skip_fn(fk):
       ^^^^^^^^^^^^^^^^^
  File "/usr/local/lib/python3.11/site-packages/sqlalchemy/orm/mapper.py", line 4033, in skip
    dep = table_to_mapper.get(fk.column.table)
                              ^^^^^^^^^
  File "/usr/local/lib/python3.11/site-packages/sqlalchemy/util/langhelpers.py", line 1141, in __get__
    obj.__dict__[self.__name__] = result = self.fget(obj)
                                           ^^^^^^^^^^^^^^
  File "/usr/local/lib/python3.11/site-packages/sqlalchemy/sql/schema.py", line 3159, in column
    return self._resolve_column()
           ^^^^^^^^^^^^^^^^^^^^^^
  File "/usr/local/lib/python3.11/site-packages/sqlalchemy/sql/schema.py", line 3182, in _resolve_column
    raise exc.NoReferencedTableError(
sqlalchemy.exc.NoReferencedTableError: Foreign key associated with column 'inferences.modelId' could not find table 'models' with which to generate a foreign key to target column 'id'
[2025-08-29: 01:30:09] [inferences] > Error saving in DB inference of 1/d704d53ae9904f25a5906644cc8897d0/original_img.jpg >> (<class 'sqlalchemy.exc.NoReferencedTableError'>, NoReferencedTableError("Foreign key associated with column 'inferences.modelId' could not find table 'models' with which to generate a foreign key to target column 'id'"), <traceback object at 0x7f01fea2a000>)
Traceback (most recent call last):
  File "/app/src/routes/inferences.py", line 155, in generateInference
    db.session.commit()
  File "/usr/local/lib/python3.11/site-packages/sqlalchemy/orm/scoping.py", line 597, in commit
    return self._proxied.commit()
           ^^^^^^^^^^^^^^^^^^^^^^
  File "/usr/local/lib/python3.11/site-packages/sqlalchemy/orm/session.py", line 2017, in commit
    trans.commit(_to_root=True)
  File "<string>", line 2, in commit
  File "/usr/local/lib/python3.11/site-packages/sqlalchemy/orm/state_changes.py", line 139, in _go
    ret_value = fn(self, *arg, **kw)
                ^^^^^^^^^^^^^^^^^^^^
  File "/usr/local/lib/python3.11/site-packages/sqlalchemy/orm/session.py", line 1302, in commit
    self._prepare_impl()
  File "<string>", line 2, in _prepare_impl
  File "/usr/local/lib/python3.11/site-packages/sqlalchemy/orm/state_changes.py", line 139, in _go
    ret_value = fn(self, *arg, **kw)
                ^^^^^^^^^^^^^^^^^^^^
  File "/usr/local/lib/python3.11/site-packages/sqlalchemy/orm/session.py", line 1277, in _prepare_impl
    self.session.flush()
  File "/usr/local/lib/python3.11/site-packages/sqlalchemy/orm/session.py", line 4341, in flush
    self._flush(objects)
  File "/usr/local/lib/python3.11/site-packages/sqlalchemy/orm/session.py", line 4476, in _flush
    with util.safe_reraise():
  File "/usr/local/lib/python3.11/site-packages/sqlalchemy/util/langhelpers.py", line 146, in __exit__
    raise exc_value.with_traceback(exc_tb)
  File "/usr/local/lib/python3.11/site-packages/sqlalchemy/orm/session.py", line 4437, in _flush
    flush_context.execute()
  File "/usr/local/lib/python3.11/site-packages/sqlalchemy/orm/unitofwork.py", line 466, in execute
    rec.execute(self)
  File "/usr/local/lib/python3.11/site-packages/sqlalchemy/orm/unitofwork.py", line 642, in execute
    util.preloaded.orm_persistence.save_obj(
  File "/usr/local/lib/python3.11/site-packages/sqlalchemy/orm/persistence.py", line 76, in save_obj
    for table, mapper in base_mapper._sorted_tables.items():
                         ^^^^^^^^^^^^^^^^^^^^^^^^^^
  File "/usr/local/lib/python3.11/site-packages/sqlalchemy/util/langhelpers.py", line 1253, in __get__
    obj.__dict__[self.__name__] = result = self.fget(obj)
                                           ^^^^^^^^^^^^^^
  File "/usr/local/lib/python3.11/site-packages/sqlalchemy/orm/mapper.py", line 4050, in _sorted_tables
    sorted_ = sql_util.sort_tables(
              ^^^^^^^^^^^^^^^^^^^^^
  File "/usr/local/lib/python3.11/site-packages/sqlalchemy/sql/ddl.py", line 1252, in sort_tables
    for (t, fkcs) in sort_tables_and_constraints(
                     ^^^^^^^^^^^^^^^^^^^^^^^^^^^^
  File "/usr/local/lib/python3.11/site-packages/sqlalchemy/sql/ddl.py", line 1322, in sort_tables_and_constraints
    filtered = filter_fn(fkc)
               ^^^^^^^^^^^^^^
  File "/usr/local/lib/python3.11/site-packages/sqlalchemy/sql/ddl.py", line 1242, in _skip_fn
    if fixed_skip_fn(fk):
       ^^^^^^^^^^^^^^^^^
  File "/usr/local/lib/python3.11/site-packages/sqlalchemy/orm/mapper.py", line 4033, in skip
    dep = table_to_mapper.get(fk.column.table)
                              ^^^^^^^^^
  File "/usr/local/lib/python3.11/site-packages/sqlalchemy/util/langhelpers.py", line 1141, in __get__
    obj.__dict__[self.__name__] = result = self.fget(obj)
                                           ^^^^^^^^^^^^^^
  File "/usr/local/lib/python3.11/site-packages/sqlalchemy/sql/schema.py", line 3159, in column
    return self._resolve_column()
           ^^^^^^^^^^^^^^^^^^^^^^
  File "/usr/local/lib/python3.11/site-packages/sqlalchemy/sql/schema.py", line 3182, in _resolve_column
    raise exc.NoReferencedTableError(
sqlalchemy.exc.NoReferencedTableError: Foreign key associated with column 'inferences.modelId' could not find table 'models' with which to generate a foreign key to target column 'id'
